Workbook

Sheet 2025
A1: TIPO DE SOLICITUD | B1: NOMBRE | C1: ENTIDAD | D1: ASUNTO | E1: RADICADO | F1: FECHA DE INGRESO DE LA SOLICITUD | G1: HORA | H1: ANEXOS | I1: PROCESO RESPONSABLE | J1: TERMINO | K1: POSIBLES DIAS RESTANTES | L1: FECHA DE VENCIMIENTO | M1: RADICADO POR | N1: ALERTA | O1: ALERTA 2 | P1: CONSECUTIVO | Q1: FECHA DE SALIDA | R1: DIAS QUE LE SOBRARON
A2: OTRO | B2: MAYRA ARTUNDUAGA | C2: ESAC | D2: DESAFILIACIONES | E2: 1 | F2: 46024 | G2: FALSE | H2: FALSE | I2: COMERCIAL | J2: =IF(A2="INFORMACIÓN O DOCUMENTOS", 10, IF(A2="CONSULTA", 30, IF(A2="FACTURACIÓN Y COBROS", 15, IF(A2="VINCULACIÓN Y DESVINCULACIÓN", 15, IF(A2="NO ES DE NUESTRA COMPETENCIA", 5, IF(A2="OTRO", 15, "")))))) -> 15 | K2: =IF(AND(F2<>"", L2<>""), NETWORKDAYS(TODAY(), L2-1, FESTIVOS!A$1:A$55), "") -> -97 | L2: =IF(AND(F2<>"", J2<>""), WORKDAY(F2, J2, FESTIVOS!A$1:A$55), "") -> 46048 | M2: LAURA GIRALDO | N2: 0 | O2: =IF(OR(K2="", J2=""), "", IF(K2<0, "Vencido", IF(K2>(J2/2), "Supere la mitad", "Bajo la mitad"))) -> Vencido | P2: CE-GC-007 | Q2: 46038 | R2: =IF(OR(Q2="", L2=""), "", NETWORKDAYS(L2, Q2, FESTIVOS!A1:A55)) -> -7
A3: OTRO | B3: MAYRA ARTUNDUAGA | C3: ESAC | D3: DESAFILIACIONES | E3: 2 | F3: 46024 | G3: FALSE | H3: FALSE | I3: COMERCIAL | J3: =IF(A3="INFORMACIÓN O DOCUMENTOS", 10, IF(A3="CONSULTA", 30, IF(A3="FACTURACIÓN Y COBROS", 15, IF(A3="VINCULACIÓN Y DESVINCULACIÓN", 15, IF(A3="NO ES DE NUESTRA COMPETENCIA", 5, IF(A3="OTRO", 15, "")))))) -> 15 | K3: =IF(AND(F3<>"", L3<>""), NETWORKDAYS(TODAY(), L3-1, FESTIVOS!A$1:A$55), "") -> -97 | L3: =IF(AND(F3<>"", J3<>""), WORKDAY(F3, J3, FESTIVOS!A$1:A$55), "") -> 46048 | M3: LAURA GIRALDO | N3: =IF(K3="", "", MAX(0, K3 - (TODAY() - TODAY()))) -> 0 | O3: =IF(OR(K3="", J3=""), "", IF(K3<0, "Vencido", IF(K3>(J3/2), "Supere la mitad", "Bajo la mitad"))) -> Vencido | P3: CE-GC-008 | Q3: 46041 | R3: =IF(OR(Q3="", L3=""), "", NETWORKDAYS(L3, Q3, FESTIVOS!A2:A56)) -> -6
A4: OTRO | B4: CARLOS ALMERO VIDEL | C4: USUARIO | D4: COTIZACIÓN | E4: 3 | F4: 46027 | G4: FALSE | H4: FALSE | I4: COMERCIAL | J4: =IF(A4="INFORMACIÓN O DOCUMENTOS", 10, IF(A4="CONSULTA", 30, IF(A4="FACTURACIÓN Y COBROS", 15, IF(A4="VINCULACIÓN Y DESVINCULACIÓN", 15, IF(A4="NO ES DE NUESTRA COMPETENCIA", 5, IF(A4="OTRO", 15, "")))))) -> 15 | K4: =IF(AND(F4<>"", L4<>""), NETWORKDAYS(TODAY(), L4-1, FESTIVOS!A$1:A$55), "") -> -97 | L4: =IF(AND(F4<>"", J4<>""), WORKDAY(F4, J4, FESTIVOS!A$1:A$55), "") -> 46049 | M4: LAURA GIRALDO | N4: =IF(K4="", "", MAX(0, K4 - (TODAY() - TODAY()))) -> 0 | O4: =IF(OR(K4="", J4=""), "", IF(K4<0, "Vencido", IF(K4>(J4/2), "Supere la mitad", "Bajo la mitad"))) -> Vencido | P4: CE-GC-0011 | Q4: 46029 | R4: =IF(OR(Q4="", L4=""), "", NETWORKDAYS(L4, Q4, FESTIVOS!A3:A57)) -> -14 | S4: si salen en engativo sobraron
A5: OTRO | B5: MAYRA ARTUNDUAGA | C5: ESAC | D5: DESAFILIACIONES | E5: 4 | F5: 46027 | G5: FALSE | H5: FALSE | I5: COMERCIAL | J5: =IF(A5="INFORMACIÓN O DOCUMENTOS", 10, IF(A5="CONSULTA", 30, IF(A5="FACTURACIÓN Y COBROS", 15, IF(A5="VINCULACIÓN Y DESVINCULACIÓN", 15, IF(A5="NO ES DE NUESTRA COMPETENCIA", 5, IF(A5="OTRO", 15, "")))))) -> 15 | K5: =IF(AND(F5<>"", L5<>""), NETWORKDAYS(TODAY(), L5-1, FESTIVOS!A$1:A$55), "") -> -97 | L5: =IF(AND(F5<>"", J5<>""), WORKDAY(F5, J5, FESTIVOS!A$1:A$55), "") -> 46049 | M5: LAURA GIRALDO | N5: =IF(K5="", "", MAX(0, K5 - (TODAY() - TODAY()))) -> 0 | O5: =IF(OR(K5="", J5=""), "", IF(K5<0, "Vencido", IF(K5>(J5/2), "Supere la mitad", "Bajo la mitad"))) -> Vencido | P5: CE-GC-0010 | Q5: 46038 | R5: =IF(OR(Q5="", L5=""), "", NETWORKDAYS(L5, Q5, FESTIVOS!A4:A58)) -> -8 | S5: si salen positivos nos pasamos
A6: OTRO | B6: EMITIDO POR LA ALCALDIA | C6: ALCALDIA | D6: TRASLADO POR COMPETENCIA -MARIA MARGARITALOPEZ GOMEZ | E6: 5 | F6: 46028 | G6: FALSE | H6: FALSE | I6: COMERCIAL | J6: =IF(A6="INFORMACIÓN O DOCUMENTOS", 10, IF(A6="CONSULTA", 30, IF(A6="FACTURACIÓN Y COBROS", 15, IF(A6="VINCULACIÓN Y DESVINCULACIÓN", 15, IF(A6="NO ES DE NUESTRA COMPETENCIA", 5, IF(A6="OTRO", 15, "")))))) -> 15 | K6: =IF(AND(F6<>"", L6<>""), NETWORKDAYS(TODAY(), L6-1, FESTIVOS!A$1:A$55), "") -> -96 | L6: =IF(AND(F6<>"", J6<>""), WORKDAY(F6, J6, FESTIVOS!A$1:A$55), "") -> 46050 | M6: LAURA GIRALDO | N6: =IF(K6="", "", MAX(0, K6 - (TODAY() - TODAY()))) -> 0 | O6: =IF(OR(K6="", J6=""), "", IF(K6<0, "Vencido", IF(K6>(J6/2), "Supere la mitad", "Bajo la mitad"))) -> Vencido | P6: CE-GC-0055 | Q6: 46038 | R6: =IF(OR(Q6="", L6=""), "", NETWORKDAYS(L6, Q6, FESTIVOS!A5:A59)) -> -9
A7: OTRO | B7: KARLA JOHANA LISCANO CORREA | C7: ALCALDIA | D7: ACTA DEL COMITÉ DE CONOCIMIENTO DE RIESGO | E7: 6 | F7: 46028 | G7: FALSE | H7: FALSE | I7: COMERCIAL | J7: =IF(A7="INFORMACIÓN O DOCUMENTOS", 10, IF(A7="CONSULTA", 30, IF(A7="FACTURACIÓN Y COBROS", 15, IF(A7="VINCULACIÓN Y DESVINCULACIÓN", 15, IF(A7="NO ES DE NUESTRA COMPETENCIA", 5, IF(A7="OTRO", 15, "")))))) -> 15 | K7: =IF(AND(F7<>"", L7<>""), NETWORKDAYS(TODAY(), L7-1, FESTIVOS!A$1:A$55), "") -> -96 | L7: =IF(AND(F7<>"", J7<>""), WORKDAY(F7, J7, FESTIVOS!A$1:A$55), "") -> 46050 | M7: LAURA GIRALDO | N7: =IF(K7="", "", MAX(0, K7 - (TODAY() - TODAY()))) -> 0 | O7: =IF(OR(K7="", J7=""), "", IF(K7<0, "Vencido", IF(K7>(J7/2), "Supere la mitad", "Bajo la mitad"))) -> Vencido | P7: NO REQUIERE RESPUESTA | Q7: FALSE | R7: =IF(OR(Q7="", L7=""), "", NETWORKDAYS(L7, Q7, FESTIVOS!A6:A60)) -> #VALUE!
A8: OTRO | B8: ESTHER JULIA GOMEZ | C8: USUARIO | D8: DERECHO DE PETICIÓN | E8: 7 | F8: 46028 | G8: FALSE | H8: FALSE | I8: COMERCIAL | J8: =IF(A8="INFORMACIÓN O DOCUMENTOS", 10, IF(A8="CONSULTA", 30, IF(A8="FACTURACIÓN Y COBROS", 15, IF(A8="VINCULACIÓN Y DESVINCULACIÓN", 15, IF(A8="NO ES DE NUESTRA COMPETENCIA", 5, IF(A8="OTRO", 15, "")))))) -> 15 | K8: =IF(AND(F8<>"", L8<>""), NETWORKDAYS(TODAY(), L8-1, FESTIVOS!A$1:A$55), "") -> -96 | L8: =IF(AND(F8<>"", J8<>""), WORKDAY(F8, J8, FESTIVOS!A$1:A$55), "") -> 46050 | M8: LAURA GIRALDO | N8: =IF(K8="", "", MAX(0, K8 - (TODAY() - TODAY()))) -> 0 | O8: =IF(OR(K8="", J8=""), "", IF(K8<0, "Vencido", IF(K8>(J8/2), "Supere la mitad", "Bajo la mitad"))) -> Vencido | P8: CE-GC-0113 | Q8: 46050 | R8: =IF(OR(Q8="", L8=""), "", NETWORKDAYS(L8, Q8, FESTIVOS!A7:A61)) -> 1
A9: OTRO | B9: OMAR JOSE MAESTRE FELIZZOLA | C9: SUPER | D9: REMISIÓN MESA DE TRABAJO | E9: 8 | F9: 46028 | G9: FALSE | H9: FALSE | I9: JURÍDICA | J9: =IF(A9="INFORMACIÓN O DOCUMENTOS", 10, IF(A9="CONSULTA", 30, IF(A9="FACTURACIÓN Y COBROS", 15, IF(A9="VINCULACIÓN Y DESVINCULACIÓN", 15, IF(A9="NO ES DE NUESTRA COMPETENCIA", 5, IF(A9="OTRO", 15, "")))))) -> 15 | K9: =IF(AND(F9<>"", L9<>""), NETWORKDAYS(TODAY(), L9-1, FESTIVOS!A$1:A$55), "") -> -96 | L9: =IF(AND(F9<>"", J9<>""), WORKDAY(F9, J9, FESTIVOS!A$1:A$55), "") -> 46050 | M9: LAURA GIRALDO | N9: =IF(K9="", "", MAX(0, K9 - (TODAY() - TODAY()))) -> 0 | O9: =IF(OR(K9="", J9=""), "", IF(K9<0, "Vencido", IF(K9>(J9/2), "Supere la mitad", "Bajo la mitad"))) -> Vencido | P9: FALSE | Q9: FALSE | R9: =IF(OR(Q9="", L9=""), "", NETWORKDAYS(L9, Q9, FESTIVOS!A8:A62)) -> #VALUE!
A10: OTRO | B10: ADRIANA GUZMÁN BUITRAGO | C10: USUARIO DE SERVINTEGRAL | D10: DERECHO DE PETICIÓN | E10: 9 | F10: 46028 | G10: FALSE | H10: FALSE | I10: COMERCIAL | J10: =IF(A10="INFORMACIÓN O DOCUMENTOS", 10, IF(A10="CONSULTA", 30, IF(A10="FACTURACIÓN Y COBROS", 15, IF(A10="VINCULACIÓN Y DESVINCULACIÓN", 15, IF(A10="NO ES DE NUESTRA COMPETENCIA", 5, IF(A10="OTRO", 15, "")))))) -> 15 | K10: =IF(AND(F10<>"", L10<>""), NETWORKDAYS(TODAY(), L10-1, FESTIVOS!A$1:A$55), "") -> -96 | L10: =IF(AND(F10<>"", J10<>""), WORKDAY(F10, J10, FESTIVOS!A$1:A$55), "") -> 46050 | M10: LAURA GIRALDO | N10: =IF(K10="", "", MAX(0, K10 - (TODAY() - TODAY()))) -> 0 | O10: =IF(OR(K10="", J10=""), "", IF(K10<0, "Vencido", IF(K10>(J10/2), "Supere la mitad", "Bajo la mitad"))) -> Vencido | P10: CE-GC-0065 | Q10: 46041 | R10: =IF(OR(Q10="", L10=""), "", NETWORKDAYS(L10, Q10, FESTIVOS!A9:A63)) -> -8
A11: OTRO | B11: GINA PAOLA RIVERA CHACON | C11: USUARIO DE SERVINTEGRAL | D11: RESPUESTA DE VINCULACIÓN | E11: 10 | F11: 46029 | G11: FALSE | H11: FALSE | I11: COMERCIAL | J11: =IF(A11="INFORMACIÓN O DOCUMENTOS", 10, IF(A11="CONSULTA", 30, IF(A11="FACTURACIÓN Y COBROS", 15, IF(A11="VINCULACIÓN Y DESVINCULACIÓN", 15, IF(A11="NO ES DE NUESTRA COMPETENCIA", 5, IF(A11="OTRO", 15, "")))))) -> 15 | K11: =IF(AND(F11<>"", L11<>""), NETWORKDAYS(TODAY(), L11-1, FESTIVOS!A$1:A$55), "") -> -95 | L11: =IF(AND(F11<>"", J11<>""), WORKDAY(F11, J11, FESTIVOS!A$1:A$55), "") -> 46051 | M11: LAURA GIRALDO | N11: =IF(K11="", "", MAX(0, K11 - (TODAY() - TODAY()))) -> 0 | O11: =IF(OR(K11="", J11=""), "", IF(K11<0, "Vencido", IF(K11>(J11/2), "Supere la mitad", "Bajo la mitad"))) -> Vencido | P11: CE-GC-0012 | Q11: 46037 | R11: =IF(OR(Q11="", L11=""), "", NETWORKDAYS(L11, Q11, FESTIVOS!A10:A64)) -> -11
A12: OTRO | B12: EQUIPO DE VERIFICACIÓN | C12: USUARIO DE SERVINTEGRAL | D12: ACTUALIZACIÓN DE INFORMACIÓN | E12: 11 | F12: 46029 | G12: FALSE | H12: FALSE | I12: JURÍDICA | J12: =IF(A12="INFORMACIÓN O DOCUMENTOS", 10, IF(A12="CONSULTA", 30, IF(A12="FACTURACIÓN Y COBROS", 15, IF(A12="VINCULACIÓN Y DESVINCULACIÓN", 15, IF(A12="NO ES DE NUESTRA COMPETENCIA", 5, IF(A12="OTRO", 15, "")))))) -> 15 | K12: =IF(AND(F12<>"", L12<>""), NETWORKDAYS(TODAY(), L12-1, FESTIVOS!A$1:A$55), "") -> -95 | L12: =IF(AND(F12<>"", J12<>""), WORKDAY(F12, J12, FESTIVOS!A$1:A$55), "") -> 46051 | M12: LAURA GIRALDO | N12: =IF(K12="", "", MAX(0, K12 - (TODAY() - TODAY()))) -> 0 | O12: =IF(OR(K12="", J12=""), "", IF(K12<0, "Vencido", IF(K12>(J12/2), "Supere la mitad", "Bajo la mitad"))) -> Vencido | P12: FALSE | Q12: FALSE | R12: =IF(OR(Q12="", L12=""), "", NETWORKDAYS(L12, Q12, FESTIVOS!A11:A65)) -> #VALUE!
A13: OTRO | B13: MARIA GLORIA CUELLAR LOZANO | C13: USUARIO DE SERVINTEGRAL | D13: INMUEBLE DESOCUPADO | E13: 12 | F13: 46030 | G13: FALSE | H13: FALSE | I13: COMERCIAL | J13: =IF(A13="INFORMACIÓN O DOCUMENTOS", 10, IF(A13="CONSULTA", 30, IF(A13="FACTURACIÓN Y COBROS", 15, IF(A13="VINCULACIÓN Y DESVINCULACIÓN", 15, IF(A13="NO ES DE NUESTRA COMPETENCIA", 5, IF(A13="OTRO", 15, "")))))) -> 15 | K13: =IF(AND(F13<>"", L13<>""), NETWORKDAYS(TODAY(), L13-1, FESTIVOS!A$1:A$55), "") -> -94 | L13: =IF(AND(F13<>"", J13<>""), WORKDAY(F13, J13, FESTIVOS!A$1:A$55), "") -> 46052 | M13: LAURA GIRALDO | N13: =IF(K13="", "", MAX(0, K13 - (TODAY() - TODAY()))) -> 0 | O13: =IF(OR(K13="", J13=""), "", IF(K13<0, "Vencido", IF(K13>(J13/2), "Supere la mitad", "Bajo la mitad"))) -> Vencido | P13: CE-GC-0033 | Q13: 46036 | R13: =IF(OR(Q13="", L13=""), "", NETWORKDAYS(L13, Q13, FESTIVOS!A12:A66)) -> -13
A14: OTRO | B14: DIANA MARCELA PERDOMO BELTRÁN | C14: SUPER | D14: Respuesta al radicado de entrada SSPD No. 20255294845332 de fecha 20 de noviembre de 2025 - Respuesta a solicitud con radicado interno 2529 del 4 de noviembre de 2025. “Radicado CE-GT-2420 (Respuesta a Radicado No. 2437 del 20 de octubre de 2025.Requerimiento Ordinario No. 49 - 3458)” | E14: 13 | F14: 46030 | G14: FALSE | H14: FALSE | I14: JURÍDICA | J14: =IF(A14="INFORMACIÓN O DOCUMENTOS", 10, IF(A14="CONSULTA", 30, IF(A14="FACTURACIÓN Y COBROS", 15, IF(A14="VINCULACIÓN Y DESVINCULACIÓN", 15, IF(A14="NO ES DE NUESTRA COMPETENCIA", 5, IF(A14="OTRO", 15, "")))))) -> 15 | K14: =IF(AND(F14<>"", L14<>""), NETWORKDAYS(TODAY(), L14-1, FESTIVOS!A$1:A$55), "") -> -94 | L14: =IF(AND(F14<>"", J14<>""), WORKDAY(F14, J14, FESTIVOS!A$1:A$55), "") -> 46052 | M14: LAURA GIRALDO | N14: =IF(K14="", "", MAX(0, K14 - (TODAY() - TODAY()))) -> 0 | O14: =IF(OR(K14="", J14=""), "", IF(K14<0, "Vencido", IF(K14>(J14/2), "Supere la mitad", "Bajo la mitad"))) -> Vencido | P14: CE-GC-0033 | Q14: 46036 | R14: =IF(OR(Q14="", L14=""), "", NETWORKDAYS(L14, Q14, FESTIVOS!A13:A67)) -> -13
A15: OTRO | B15: ISMAEL SILVA ALVAREZ | C15: GAS CAQUETA | D15: SOLICITUD DE CERTIFICADO | E15: 14 | F15: 46030 | G15: FALSE | H15: FALSE | I15: COMERCIAL | J15: =IF(A15="INFORMACIÓN O DOCUMENTOS", 10, IF(A15="CONSULTA", 30, IF(A15="FACTURACIÓN Y COBROS", 15, IF(A15="VINCULACIÓN Y DESVINCULACIÓN", 15, IF(A15="NO ES DE NUESTRA COMPETENCIA", 5, IF(A15="OTRO", 15, "")))))) -> 15 | K15: =IF(AND(F15<>"", L15<>""), NETWORKDAYS(TODAY(), L15-1, FESTIVOS!A$1:A$55), "") -> -94 | L15: =IF(AND(F15<>"", J15<>""), WORKDAY(F15, J15, FESTIVOS!A$1:A$55), "") -> 46052 | M15: LAURA GIRALDO | N15: =IF(K15="", "", MAX(0, K15 - (TODAY() - TODAY()))) -> 0 | O15: =IF(OR(K15="", J15=""), "", IF(K15<0, "Vencido", IF(K15>(J15/2), "Supere la mitad", "Bajo la mitad"))) -> Vencido | P15: CE-GC-0014 | Q15: 46035 | R15: =IF(OR(Q15="", L15=""), "", NETWORKDAYS(L15, Q15, FESTIVOS!A14:A68)) -> -14
A16: OTRO | B16: LORENA CASTAÑO | C16: SAMAMB | D16: CARACTERIZACIÓN | E16: 15 | F16: 46030 | G16: FALSE | H16: FALSE | I16: RESIDUOS | J16: =IF(A16="INFORMACIÓN O DOCUMENTOS", 10, IF(A16="CONSULTA", 30, IF(A16="FACTURACIÓN Y COBROS", 15, IF(A16="VINCULACIÓN Y DESVINCULACIÓN", 15, IF(A16="NO ES DE NUESTRA COMPETENCIA", 5, IF(A16="OTRO", 15, "")))))) -> 15 | K16: =IF(AND(F16<>"", L16<>""), NETWORKDAYS(TODAY(), L16-1, FESTIVOS!A$1:A$55), "") -> -94 | L16: =IF(AND(F16<>"", J16<>""), WORKDAY(F16, J16, FESTIVOS!A$1:A$55), "") -> 46052 | M16: LAURA GIRALDO | N16: =IF(K16="", "", MAX(0, K16 - (TODAY() - TODAY()))) -> 0 | O16: =IF(OR(K16="", J16=""), "", IF(K16<0, "Vencido", IF(K16>(J16/2), "Supere la mitad", "Bajo la mitad"))) -> Vencido | P16: NO REQUIERE RESPUESTA | Q16: FALSE | R16: =IF(OR(Q16="", L16=""), "", NETWORKDAYS(L16, Q16, FESTIVOS!A15:A69)) -> #VALUE!
A17: OTRO | B17: LORENA CASTAÑO | C17: SAMAMB | D17: PROPUESTA | E17: 16 | F17: 46030 | G17: FALSE | H17: FALSE | I17: COMERCIAL | J17: =IF(A17="INFORMACIÓN O DOCUMENTOS", 10, IF(A17="CONSULTA", 30, IF(A17="FACTURACIÓN Y COBROS", 15, IF(A17="VINCULACIÓN Y DESVINCULACIÓN", 15, IF(A17="NO ES DE NUESTRA COMPETENCIA", 5, IF(A17="OTRO", 15, "")))))) -> 15 | K17: =IF(AND(F17<>"", L17<>""), NETWORKDAYS(TODAY(), L17-1, FESTIVOS!A$1:A$55), "") -> -94 | L17: =IF(AND(F17<>"", J17<>""), WORKDAY(F17, J17, FESTIVOS!A$1:A$55), "") -> 46052 | M17: LAURA GIRALDO | N17: =IF(K17="", "", MAX(0, K17 - (TODAY() - TODAY()))) -> 0 | O17: =IF(OR(K17="", J17=""), "", IF(K17<0, "Vencido", IF(K17>(J17/2), "Supere la mitad", "Bajo la mitad"))) -> Vencido | P17: NO REQUIERE RESPUESTA | Q17: FALSE | R17: =IF(OR(Q17="", L17=""), "", NETWORKDAYS(L17, Q17, FESTIVOS!A16:A70)) -> #VALUE!
A18: OTRO | B18: FREDY HERNAN TEJADA | C18: ELECTROCAQUETA | D18: Respuesta a oficio CE-GC-0002 del 05-01-2026 con Rad interno No 2026-1-1-75 del 06-01-2026 | E18: 17 | F18: 46030 | G18: FALSE | H18: FALSE | I18: COMERCIAL | J18: =IF(A18="INFORMACIÓN O DOCUMENTOS", 10, IF(A18="CONSULTA", 30, IF(A18="FACTURACIÓN Y COBROS", 15, IF(A18="VINCULACIÓN Y DESVINCULACIÓN", 15, IF(A18="NO ES DE NUESTRA COMPETENCIA", 5, IF(A18="OTRO", 15, "")))))) -> 15 | K18: =IF(AND(F18<>"", L18<>""), NETWORKDAYS(TODAY(), L18-1, FESTIVOS!A$1:A$55), "") -> -94 | L18: =IF(AND(F18<>"", J18<>""), WORKDAY(F18, J18, FESTIVOS!A$1:A$55), "") -> 46052 | M18: LAURA GIRALDO | N18: =IF(K18="", "", MAX(0, K18 - (TODAY() - TODAY()))) -> 0 | O18: =IF(OR(K18="", J18=""), "", IF(K18<0, "Vencido", IF(K18>(J18/2), "Supere la mitad", "Bajo la mitad"))) -> Vencido | P18: NO REQUIERE RESPUESTA | Q18: FALSE | R18: =IF(OR(Q18="", L18=""), "", NETWORKDAYS(L18, Q18, FESTIVOS!A17:A71)) -> #VALUE!
A19: OTRO | B19: FREDY HERNAN TEJADA | C19: ELECTROCAQUETA | D19: Respuesta a oficio CE-GC-0001 del 05-1-2026 con Rad interno No 2026-1-1-74 del 06-01-2026 | E19: 18 | F19: 46031 | G19: FALSE | H19: FALSE | I19: COMERCIAL | J19: =IF(A19="INFORMACIÓN O DOCUMENTOS", 10, IF(A19="CONSULTA", 30, IF(A19="FACTURACIÓN Y COBROS", 15, IF(A19="VINCULACIÓN Y DESVINCULACIÓN", 15, IF(A19="NO ES DE NUESTRA COMPETENCIA", 5, IF(A19="OTRO", 15, "")))))) -> 15 | K19: =IF(AND(F19<>"", L19<>""), NETWORKDAYS(TODAY(), L19-1, FESTIVOS!A$1:A$55), "") -> -92 | L19: =IF(AND(F19<>"", J19<>""), WORKDAY(F19, J19, FESTIVOS!A$1:A$55), "") -> 46055 | M19: LAURA GIRALDO | N19: =IF(K19="", "", MAX(0, K19 - (TODAY() - TODAY()))) -> 0 | O19: =IF(OR(K19="", J19=""), "", IF(K19<0, "Vencido", IF(K19>(J19/2), "Supere la mitad", "Bajo la mitad"))) -> Vencido | P19: NO REQUIERE RESPUESTA | Q19: FALSE | R19: =IF(OR(Q19="", L19=""), "", NETWORKDAYS(L19, Q19, FESTIVOS!A18:A72)) -> #VALUE!
A20: OTRO | B20: LUZ ELIANA TOBON MUÑOZ | C20: USUARIO DE SERVINTEGRAL | D20: SOLICITD DE ESCOMBROS | E20: 19 | F20: 46031 | G20: FALSE | H20: FALSE | I20: COMERCIAL | J20: =IF(A20="INFORMACIÓN O DOCUMENTOS", 10, IF(A20="CONSULTA", 30, IF(A20="FACTURACIÓN Y COBROS", 15, IF(A20="VINCULACIÓN Y DESVINCULACIÓN", 15, IF(A20="NO ES DE NUESTRA COMPETENCIA", 5, IF(A20="OTRO", 15, "")))))) -> 15 | K20: =IF(AND(F20<>"", L20<>""), NETWORKDAYS(TODAY(), L20-1, FESTIVOS!A$1:A$55), "") -> -92 | L20: =IF(AND(F20<>"", J20<>""), WORKDAY(F20, J20, FESTIVOS!A$1:A$55), "") -> 46055 | M20: LAURA GIRALDO | N20: =IF(K20="", "", MAX(0, K20 - (TODAY() - TODAY()))) -> 0 | O20: =IF(OR(K20="", J20=""), "", IF(K20<0, "Vencido", IF(K20>(J20/2), "Supere la mitad", "Bajo la mitad"))) -> Vencido | P20: CE-GC-0073 | Q20: 46043 | R20: =IF(OR(Q20="", L20=""), "", NETWORKDAYS(L20, Q20, FESTIVOS!A19:A73)) -> -9
A21: OTRO | B21: NANCY BOHORQUEZ | C21: USUARIO DE SERVINTEGRAL | D21: SOLICITD DE DESCUENTO EN LA DEUDA DE ASEO | E21: 20 | F21: 46035 | G21: FALSE | H21: FALSE | I21: COMERCIAL | J21: =IF(A21="INFORMACIÓN O DOCUMENTOS", 10, IF(A21="CONSULTA", 30, IF(A21="FACTURACIÓN Y COBROS", 15, IF(A21="VINCULACIÓN Y DESVINCULACIÓN", 15, IF(A21="NO ES DE NUESTRA COMPETENCIA", 5, IF(A21="OTRO", 15, "")))))) -> 15 | K21: =IF(AND(F21<>"", L21<>""), NETWORKDAYS(TODAY(), L21-1, FESTIVOS!A$1:A$55), "") -> -92 | L21: =IF(AND(F21<>"", J21<>""), WORKDAY(F21, J21, FESTIVOS!A$1:A$55), "") -> 46056 | M21: LAURA GIRALDO | N21: =IF(K21="", "", MAX(0, K21 - (TODAY() - TODAY()))) -> 0 | O21: FALSE | P21: CE-GC-0050 | Q21: 46037 | R21: =IF(OR(Q21="", L21=""), "", NETWORKDAYS(L21, Q21, FESTIVOS!A20:A74)) -> -14
A22: OTRO | B22: EMA | C22: USUARIO DE SERVINTEGRAL | D22: REFERENCIAS PERSONALES | E22: 21 | F22: 46035 | G22: FALSE | H22: FALSE | I22: TALENTO HUMANO | J22: =IF(A22="INFORMACIÓN O DOCUMENTOS", 10, IF(A22="CONSULTA", 30, IF(A22="FACTURACIÓN Y COBROS", 15, IF(A22="VINCULACIÓN Y DESVINCULACIÓN", 15, IF(A22="NO ES DE NUESTRA COMPETENCIA", 5, IF(A22="OTRO", 15, "")))))) -> 15 | K22: =IF(AND(F22<>"", L22<>""), NETWORKDAYS(TODAY(), L22-1, FESTIVOS!A$1:A$55), "") -> -92 | L22: =IF(AND(F22<>"", J22<>""), WORKDAY(F22, J22, FESTIVOS!A$1:A$55), "") -> 46056 | M22: LAURA GIRALDO | N22: =IF(K22="", "", MAX(0, K22 - (TODAY() - TODAY()))) -> 0 | O22: =IF(OR(K22="", J22=""), "", IF(K22<0, "Vencido", IF(K22>(J22/2), "Supere la mitad", "Bajo la mitad"))) -> Vencido | P22: NO REQUIERE RESPUESTA | Q22: FALSE | R22: =IF(OR(Q22="", L22=""), "", NETWORKDAYS(L22, Q22, FESTIVOS!A21:A75)) -> #VALUE!
A23: OTRO | B23: LEONOR RODRIGUEZ CELIS | C23: USUARIO DE SERVINTEGRAL | D23: AGRADECIMIENTO | E23: 22 | F23: 46035 | G23: FALSE | H23: FALSE | I23: RESIDUOS | J23: =IF(A23="INFORMACIÓN O DOCUMENTOS", 10, IF(A23="CONSULTA", 30, IF(A23="FACTURACIÓN Y COBROS", 15, IF(A23="VINCULACIÓN Y DESVINCULACIÓN", 15, IF(A23="NO ES DE NUESTRA COMPETENCIA", 5, IF(A23="OTRO", 15, "")))))) -> 15 | K23: =IF(AND(F23<>"", L23<>""), NETWORKDAYS(TODAY(), L23-1, FESTIVOS!A$1:A$55), "") -> -92 | L23: =IF(AND(F23<>"", J23<>""), WORKDAY(F23, J23, FESTIVOS!A$1:A$55), "") -> 46056 | M23: LAURA GIRALDO | N23: =IF(K23="", "", MAX(0, K23 - (TODAY() - TODAY()))) -> 0 | O23: =IF(OR(K23="", J23=""), "", IF(K23<0, "Vencido", IF(K23>(J23/2), "Supere la mitad", "Bajo la mitad"))) -> Vencido | P23: CE-GC-0033 | Q23: 46036 | R23: =IF(OR(Q23="", L23=""), "", NETWORKDAYS(L23, Q23, FESTIVOS!A22:A76)) -> -15
A24: OTRO | B24: YULIANA ESCOBAR | C24: ESAC | D24: NOTIFICACIÓN PERSONAL | E24: 23 | F24: 46035 | G24: FALSE | H24: FALSE | I24: COMERCIAL | J24: =IF(A24="INFORMACIÓN O DOCUMENTOS", 10, IF(A24="CONSULTA", 30, IF(A24="FACTURACIÓN Y COBROS", 15, IF(A24="VINCULACIÓN Y DESVINCULACIÓN", 15, IF(A24="NO ES DE NUESTRA COMPETENCIA", 5, IF(A24="OTRO", 15, "")))))) -> 15 | K24: =IF(AND(F24<>"", L24<>""), NETWORKDAYS(TODAY(), L24-1, FESTIVOS!A$1:A$55), "") -> -92 | L24: =IF(AND(F24<>"", J24<>""), WORKDAY(F24, J24, FESTIVOS!A$1:A$55), "") -> 46056 | M24: LAURA GIRALDO | N24: =IF(K24="", "", MAX(0, K24 - (TODAY() - TODAY()))) -> 0 | O24: =IF(OR(K24="", J24=""), "", IF(K24<0, "Vencido", IF(K24>(J24/2), "Supere la mitad", "Bajo la mitad"))) -> Vencido | P24: CE-GC-0033 | Q24: 46036 | R24: =IF(OR(Q24="", L24=""), "", NETWORKDAYS(L24, Q24, FESTIVOS!A23:A77)) -> -15
A25: OTRO | B25: YULIANA ESCOBAR | C25: ESAC | D25: NOTIFICACIÓN PERSONAL | E25: 24 | F25: 46035 | G25: FALSE | H25: FALSE | I25: COMERCIAL | J25: =IF(A25="INFORMACIÓN O DOCUMENTOS", 10, IF(A25="CONSULTA", 30, IF(A25="FACTURACIÓN Y COBROS", 15, IF(A25="VINCULACIÓN Y DESVINCULACIÓN", 15, IF(A25="NO ES DE NUESTRA COMPETENCIA", 5, IF(A25="OTRO", 15, "")))))) -> 15 | K25: =IF(AND(F25<>"", L25<>""), NETWORKDAYS(TODAY(), L25-1, FESTIVOS!A$1:A$55), "") -> -92 | L25: =IF(AND(F25<>"", J25<>""), WORKDAY(F25, J25, FESTIVOS!A$1:A$55), "") -> 46056 | M25: LAURA GIRALDO | N25: =IF(K25="", "", MAX(0, K25 - (TODAY() - TODAY()))) -> 0 | O25: =IF(OR(K25="", J25=""), "", IF(K25<0, "Vencido", IF(K25>(J25/2), "Supere la mitad", "Bajo la mitad"))) -> Vencido | P25: CE-GC-0033 | Q25: 46036 | R25: =IF(OR(Q25="", L25=""), "", NETWORKDAYS(L25, Q25, FESTIVOS!A24:A78)) -> -15
A26: OTRO | B26: YULIANA ESCOBAR | C26: ESAC | D26: NOTIFICACIÓN PERSONAL | E26: 25 | F26: 46035 | G26: FALSE | H26: FALSE | I26: COMERCIAL | J26: =IF(A26="INFORMACIÓN O DOCUMENTOS", 10, IF(A26="CONSULTA", 30, IF(A26="FACTURACIÓN Y COBROS", 15, IF(A26="VINCULACIÓN Y DESVINCULACIÓN", 15, IF(A26="NO ES DE NUESTRA COMPETENCIA", 5, IF(A26="OTRO", 15, "")))))) -> 15 | K26: =IF(AND(F26<>"", L26<>""), NETWORKDAYS(TODAY(), L26-1, FESTIVOS!A$1:A$55), "") -> -92 | L26: =IF(AND(F26<>"", J26<>""), WORKDAY(F26, J26, FESTIVOS!A$1:A$55), "") -> 46056 | M26: LAURA GIRALDO | N26: =IF(K26="", "", MAX(0, K26 - (TODAY() - TODAY()))) -> 0 | O26: =IF(OR(K26="", J26=""), "", IF(K26<0, "Vencido", IF(K26>(J26/2), "Supere la mitad", "Bajo la mitad"))) -> Vencido | P26: CE-GC-0033 | Q26: 46036 | R26: =IF(OR(Q26="", L26=""), "", NETWORKDAYS(L26, Q26, FESTIVOS!A25:A79)) -> -15
A27: OTRO | B27: YULIANA ESCOBAR | C27: ESAC | D27: NOTIFICACIÓN PERSONAL | E27: 26 | F27: 46035 | G27: FALSE | H27: FALSE | I27: COMERCIAL | J27: =IF(A27="INFORMACIÓN O DOCUMENTOS", 10, IF(A27="CONSULTA", 30, IF(A27="FACTURACIÓN Y COBROS", 15, IF(A27="VINCULACIÓN Y DESVINCULACIÓN", 15, IF(A27="NO ES DE NUESTRA COMPETENCIA", 5, IF(A27="OTRO", 15, "")))))) -> 15 | K27: =IF(AND(F27<>"", L27<>""), NETWORKDAYS(TODAY(), L27-1, FESTIVOS!A$1:A$55), "") -> -92 | L27: =IF(AND(F27<>"", J27<>""), WORKDAY(F27, J27, FESTIVOS!A$1:A$55), "") -> 46056 | M27: LAURA GIRALDO | N27: =IF(K27="", "", MAX(0, K27 - (TODAY() - TODAY()))) -> 0 | O27: =IF(OR(K27="", J27=""), "", IF(K27<0, "Vencido", IF(K27>(J27/2), "Supere la mitad", "Bajo la mitad"))) -> Vencido | P27: CE-GC-0033 | Q27: 46036 | R27: =IF(OR(Q27="", L27=""), "", NETWORKDAYS(L27, Q27, FESTIVOS!A26:A80)) -> -15
A28: OTRO | B28: YULIANA ESCOBAR | C28: ESAC | D28: NOTIFICACIÓN PERSONAL | E28: 27 | F28: 46035 | G28: FALSE | H28: FALSE | I28: COMERCIAL | J28: =IF(A28="INFORMACIÓN O DOCUMENTOS", 10, IF(A28="CONSULTA", 30, IF(A28="FACTURACIÓN Y COBROS", 15, IF(A28="VINCULACIÓN Y DESVINCULACIÓN", 15, IF(A28="NO ES DE NUESTRA COMPETENCIA", 5, IF(A28="OTRO", 15, "")))))) -> 15 | K28: =IF(AND(F28<>"", L28<>""), NETWORKDAYS(TODAY(), L28-1, FESTIVOS!A$1:A$55), "") -> -92 | L28: =IF(AND(F28<>"", J28<>""), WORKDAY(F28, J28, FESTIVOS!A$1:A$55), "") -> 46056 | M28: LAURA GIRALDO | N28: =IF(K28="", "", MAX(0, K28 - (TODAY() - TODAY()))) -> 0 | O28: =IF(OR(K28="", J28=""), "", IF(K28<0, "Vencido", IF(K28>(J28/2), "Supere la mitad", "Bajo la mitad"))) -> Vencido | P28: CE-GC-0033 | Q28: 46036 | R28: =IF(OR(Q28="", L28=""), "", NETWORKDAYS(L28, Q28, FESTIVOS!A27:A81)) -> -15
A29: OTRO | B29: WILLIAM EDMUNDO PIEDRAHITA MAYA | C29: CORPOAMAZONIA | D29: TRASLADO POR COMPETENCIA | E29: 28 | F29: 46035 | G29: FALSE | H29: FALSE | I29: COMERCIAL | J29: =IF(A29="INFORMACIÓN O DOCUMENTOS", 10, IF(A29="CONSULTA", 30, IF(A29="FACTURACIÓN Y COBROS", 15, IF(A29="VINCULACIÓN Y DESVINCULACIÓN", 15, IF(A29="NO ES DE NUESTRA COMPETENCIA", 5, IF(A29="OTRO", 15, "")))))) -> 15 | K29: =IF(AND(F29<>"", L29<>""), NETWORKDAYS(TODAY(), L29-1, FESTIVOS!A$1:A$55), "") -> -92 | L29: =IF(AND(F29<>"", J29<>""), WORKDAY(F29, J29, FESTIVOS!A$1:A$55), "") -> 46056 | M29: LAURA GIRALDO | N29: =IF(K29="", "", MAX(0, K29 - (TODAY() - TODAY()))) -> 0 | O29: =IF(OR(K29="", J29=""), "", IF(K29<0, "Vencido", IF(K29>(J29/2), "Supere la mitad", "Bajo la mitad"))) -> Vencido | P29: CE-GC-0033 | Q29: 46036 | R29: =IF(OR(Q29="", L29=""), "", NETWORKDAYS(L29, Q29, FESTIVOS!A28:A82)) -> -15
A30: OTRO | B30: LUIS MANUEL ESPINOSA CALDERON | C30: ALCALDIA | D30: SOLICITUD DE INFORMACIÓN PARA LIQUIDAR EL CONCURSO ECONOMICO | E30: 29 | F30: 46036 | G30: FALSE | H30: FALSE | I30: COMERCIAL | J30: =IF(A30="INFORMACIÓN O DOCUMENTOS", 10, IF(A30="CONSULTA", 30, IF(A30="FACTURACIÓN Y COBROS", 15, IF(A30="VINCULACIÓN Y DESVINCULACIÓN", 15, IF(A30="NO ES DE NUESTRA COMPETENCIA", 5, IF(A30="OTRO", 15, "")))))) -> 15 | K30: =IF(AND(F30<>"", L30<>""), NETWORKDAYS(TODAY(), L30-1, FESTIVOS!A$1:A$55), "") -> -91 | L30: =IF(AND(F30<>"", J30<>""), WORKDAY(F30, J30, FESTIVOS!A$1:A$55), "") -> 46057 | M30: LAURA GIRALDO | N30: =IF(K30="", "", MAX(0, K30 - (TODAY() - TODAY()))) -> 0 | O30: =IF(OR(K30="", J30=""), "", IF(K30<0, "Vencido", IF(K30>(J30/2), "Supere la mitad", "Bajo la mitad"))) -> Vencido | P30: CE-GC-0033 | Q30: 46036 | R30: =IF(OR(Q30="", L30=""), "", NETWORKDAYS(L30, Q30, FESTIVOS!A29:A83)) -> -16
A31: OTRO | B31: Javier Hernán Puyo Plazas | C31: MINESTERIO DE TRABAJO | D31: Derecho de Petición fechado el día 23/12/2025 | E31: 30 | F31: 46036 | G31: FALSE | H31: FALSE | I31: TALENTO HUMANO | J31: =IF(A31="INFORMACIÓN O DOCUMENTOS", 10, IF(A31="CONSULTA", 30, IF(A31="FACTURACIÓN Y COBROS", 15, IF(A31="VINCULACIÓN Y DESVINCULACIÓN", 15, IF(A31="NO ES DE NUESTRA COMPETENCIA", 5, IF(A31="OTRO", 15, "")))))) -> 15 | K31: =IF(AND(F31<>"", L31<>""), NETWORKDAYS(TODAY(), L31-1, FESTIVOS!A$1:A$55), "") -> -91 | L31: =IF(AND(F31<>"", J31<>""), WORKDAY(F31, J31, FESTIVOS!A$1:A$55), "") -> 46057 | M31: LAURA GIRALDO | N31: =IF(K31="", "", MAX(0, K31 - (TODAY() - TODAY()))) -> 0 | O31: =IF(OR(K31="", J31=""), "", IF(K31<0, "Vencido", IF(K31>(J31/2), "Supere la mitad", "Bajo la mitad"))) -> Vencido | P31: CE-GC-0033 | Q31: 46036 | R31: =IF(OR(Q31="", L31=""), "", NETWORKDAYS(L31, Q31, FESTIVOS!A30:A84)) -> -16
A32: OTRO | B32: LUIS ZAPATA OROZCO | C32: USUARIO DE SERVINTEGRAL | D32: SOLICITUD DE 1 LETRERO | E32: 31 | F32: 46036 | G32: FALSE | H32: FALSE | I32: COMERCIAL | J32: =IF(A32="INFORMACIÓN O DOCUMENTOS", 10, IF(A32="CONSULTA", 30, IF(A32="FACTURACIÓN Y COBROS", 15, IF(A32="VINCULACIÓN Y DESVINCULACIÓN", 15, IF(A32="NO ES DE NUESTRA COMPETENCIA", 5, IF(A32="OTRO", 15, "")))))) -> 15 | K32: =IF(AND(F32<>"", L32<>""), NETWORKDAYS(TODAY(), L32-1, FESTIVOS!A$1:A$55), "") -> -91 | L32: =IF(AND(F32<>"", J32<>""), WORKDAY(F32, J32, FESTIVOS!A$1:A$55), "") -> 46057 | M32: LAURA GIRALDO | N32: =IF(K32="", "", MAX(0, K32 - (TODAY() - TODAY()))) -> 0 | O32: =IF(OR(K32="", J32=""), "", IF(K32<0, "Vencido", IF(K32>(J32/2), "Supere la mitad", "Bajo la mitad"))) -> Vencido | P32: CE-GC-0033 | Q32: 46036 | R32: =IF(OR(Q32="", L32=""), "", NETWORKDAYS(L32, Q32, FESTIVOS!A31:A85)) -> -16
A33: OTRO | B33: CLAUDIA TOVAR | C33: USUARIO DE SERVINTEGRAL | D33: VINCULACIÓN DIRECTA | E33: 32 | F33: 46036 | G33: FALSE | H33: FALSE | I33: COMERCIAL | J33: =IF(A33="INFORMACIÓN O DOCUMENTOS", 10, IF(A33="CONSULTA", 30, IF(A33="FACTURACIÓN Y COBROS", 15, IF(A33="VINCULACIÓN Y DESVINCULACIÓN", 15, IF(A33="NO ES DE NUESTRA COMPETENCIA", 5, IF(A33="OTRO", 15, "")))))) -> 15 | K33: =IF(AND(F33<>"", L33<>""), NETWORKDAYS(TODAY(), L33-1, FESTIVOS!A$1:A$55), "") -> -91 | L33: =IF(AND(F33<>"", J33<>""), WORKDAY(F33, J33, FESTIVOS!A$1:A$55), "") -> 46057 | M33: LAURA GIRALDO | N33: =IF(K33="", "", MAX(0, K33 - (TODAY() - TODAY()))) -> 0 | O33: =IF(OR(K33="", J33=""), "", IF(K33<0, "Vencido", IF(K33>(J33/2), "Supere la mitad", "Bajo la mitad"))) -> Vencido | P33: CE-GC-0033 | Q33: 46036 | R33: =IF(OR(Q33="", L33=""), "", NETWORKDAYS(L33, Q33, FESTIVOS!A32:A86)) -> -16
A34: OTRO | B34: MARIA IRAIDES HERRERA GAITAN | C34: USUARIO DE SERVINTEGRAL | D34: VINCULACIÓN DIRECTA | E34: 33 | F34: 46036 | G34: FALSE | H34: FALSE | I34: COMERCIAL | J34: =IF(A34="INFORMACIÓN O DOCUMENTOS", 10, IF(A34="CONSULTA", 30, IF(A34="FACTURACIÓN Y COBROS", 15, IF(A34="VINCULACIÓN Y DESVINCULACIÓN", 15, IF(A34="NO ES DE NUESTRA COMPETENCIA", 5, IF(A34="OTRO", 15, "")))))) -> 15 | K34: =IF(AND(F34<>"", L34<>""), NETWORKDAYS(TODAY(), L34-1, FESTIVOS!A$1:A$55), "") -> -91 | L34: =IF(AND(F34<>"", J34<>""), WORKDAY(F34, J34, FESTIVOS!A$1:A$55), "") -> 46057 | M34: LAURA GIRALDO | N34: =IF(K34="", "", MAX(0, K34 - (TODAY() - TODAY()))) -> 0 | O34: =IF(OR(K34="", J34=""), "", IF(K34<0, "Vencido", IF(K34>(J34/2), "Supere la mitad", "Bajo la mitad"))) -> Vencido | P34: CE-GC-0033 | Q34: 46036 | R34: =IF(OR(Q34="", L34=""), "", NETWORKDAYS(L34, Q34, FESTIVOS!A33:A87)) -> -16
... A185: OTRO | B185: LIGIA CONSTANZA ROJA MEJIA | C185: USUARIO DE SERVINTEGRAL | D185: Invitación reunión con Pares Académicos – Programa Administración Financiera | E185: 184 | F185: 46062 | G185: FALSE | H185: FALSE | I185: FINANCIERA | J185: =IF(A185="INFORMACIÓN O DOCUMENTOS", 10, IF(A185="CONSULTA", 30, IF(A185="FACTURACIÓN Y COBROS", 15, IF(A185="VINCULACIÓN Y DESVINCULACIÓN", 15, IF(A185="NO ES DE NUESTRA COMPETENCIA", 5, IF(A185="OTRO", 15, "")))))) -> 15 | K185: =IF(AND(F185<>"", L185<>""), NETWORKDAYS(TODAY(), L185-1, FESTIVOS!A$1:A$55), "") -> -72 | L185: =IF(AND(F185<>"", J185<>""), WORKDAY(F185, J185, FESTIVOS!A$1:A$55), "") -> 46083 | M185: LAURA GIRALDO | N185: =IF(K185="", "", MAX(0, K185 - (TODAY() - TODAY()))) -> 0 | O185: =IF(OR(K185="", J185=""), "", IF(K185<0, "Vencido", IF(K185>(J185/2), "Supere la mitad", "Bajo la mitad"))) -> Vencido | P185: CE-GC-0033 | Q185: 46036 | R185: =IF(OR(Q185="", L185=""), "", NETWORKDAYS(L185, Q185, FESTIVOS!A184:A238)) -> -34
A186: OTRO | B186: YEISON JULIAN CELIS | C186: TRABAJADOR DE SERVINTEGRAL | D186: Constancia sobre reunión del 6 de febrero de 2026 – Radicado No. 0125 | E186: 185 | F186: 46062 | G186: FALSE | H186: FALSE | J186: =IF(A186="INFORMACIÓN O DOCUMENTOS", 10, IF(A186="CONSULTA", 30, IF(A186="FACTURACIÓN Y COBROS", 15, IF(A186="VINCULACIÓN Y DESVINCULACIÓN", 15, IF(A186="NO ES DE NUESTRA COMPETENCIA", 5, IF(A186="OTRO", 15, "")))))) -> 15 | K186: =IF(AND(F186<>"", L186<>""), NETWORKDAYS(TODAY(), L186-1, FESTIVOS!A$1:A$55), "") -> -72 | L186: =IF(AND(F186<>"", J186<>""), WORKDAY(F186, J186, FESTIVOS!A$1:A$55), "") -> 46083 | M186: LAURA GIRALDO | N186: =IF(K186="", "", MAX(0, K186 - (TODAY() - TODAY()))) -> 0 | O186: =IF(OR(K186="", J186=""), "", IF(K186<0, "Vencido", IF(K186>(J186/2), "Supere la mitad", "Bajo la mitad"))) -> Vencido | P186: CE-GH-0228 | Q186: 46069 | R186: =IF(OR(Q186="", L186=""), "", NETWORKDAYS(L186, Q186, FESTIVOS!A185:A239)) -> -11
A187: OTRO | B187: OSCAR JAVIER RAMOS | C187: USUARIO DE SERVINTEGRAL | D187: Solicitud de apoyo para jornada de aseo y embellecimiento I.E. ANDES SEDE ALPES | E187: 186 | F187: 46062 | G187: FALSE | H187: FALSE | J187: =IF(A187="INFORMACIÓN O DOCUMENTOS", 10, IF(A187="CONSULTA", 30, IF(A187="FACTURACIÓN Y COBROS", 15, IF(A187="VINCULACIÓN Y DESVINCULACIÓN", 15, IF(A187="NO ES DE NUESTRA COMPETENCIA", 5, IF(A187="OTRO", 15, "")))))) -> 15 | K187: =IF(AND(F187<>"", L187<>""), NETWORKDAYS(TODAY(), L187-1, FESTIVOS!A$1:A$55), "") -> -72 | L187: =IF(AND(F187<>"", J187<>""), WORKDAY(F187, J187, FESTIVOS!A$1:A$55), "") -> 46083 | M187: LAURA GIRALDO | N187: =IF(K187="", "", MAX(0, K187 - (TODAY() - TODAY()))) -> 0 | O187: =IF(OR(K187="", J187=""), "", IF(K187<0, "Vencido", IF(K187>(J187/2), "Supere la mitad", "Bajo la mitad"))) -> Vencido | P187: CE-GC-0033 | Q187: 46036 | R187: =IF(OR(Q187="", L187=""), "", NETWORKDAYS(L187, Q187, FESTIVOS!A186:A240)) -> -34
A188: OTRO | B188: ARISTIDES TOVAR | C188: USUARIO DE SERVINTEGRAL | D188: ENCUENTRO NACIONAL | E188: 187 | F188: 46062 | G188: FALSE | H188: FALSE | J188: =IF(A188="INFORMACIÓN O DOCUMENTOS", 10, IF(A188="CONSULTA", 30, IF(A188="FACTURACIÓN Y COBROS", 15, IF(A188="VINCULACIÓN Y DESVINCULACIÓN", 15, IF(A188="NO ES DE NUESTRA COMPETENCIA", 5, IF(A188="OTRO", 15, "")))))) -> 15 | K188: =IF(AND(F188<>"", L188<>""), NETWORKDAYS(TODAY(), L188-1, FESTIVOS!A$1:A$55), "") -> -72 | L188: =IF(AND(F188<>"", J188<>""), WORKDAY(F188, J188, FESTIVOS!A$1:A$55), "") -> 46083 | M188: LAURA GIRALDO | N188: =IF(K188="", "", MAX(0, K188 - (TODAY() - TODAY()))) -> 0 | O188: =IF(OR(K188="", J188=""), "", IF(K188<0, "Vencido", IF(K188>(J188/2), "Supere la mitad", "Bajo la mitad"))) -> Vencido | P188: CE-GC-0033 | Q188: 46036 | R188: =IF(OR(Q188="", L188=""), "", NETWORKDAYS(L188, Q188, FESTIVOS!A187:A241)) -> -34
A189: OTRO | B189: QUEJA DEL SERVICIO | C189: USUARIO DE SERVINTEGRAL | D189: EVIDALIA LADINO | E189: 188 | F189: 46062 | G189: FALSE | H189: FALSE | J189: =IF(A189="INFORMACIÓN O DOCUMENTOS", 10, IF(A189="CONSULTA", 30, IF(A189="FACTURACIÓN Y COBROS", 15, IF(A189="VINCULACIÓN Y DESVINCULACIÓN", 15, IF(A189="NO ES DE NUESTRA COMPETENCIA", 5, IF(A189="OTRO", 15, "")))))) -> 15 | K189: =IF(AND(F189<>"", L189<>""), NETWORKDAYS(TODAY(), L189-1, FESTIVOS!A$1:A$55), "") -> -72 | L189: =IF(AND(F189<>"", J189<>""), WORKDAY(F189, J189, FESTIVOS!A$1:A$55), "") -> 46083 | M189: LAURA GIRALDO | N189: =IF(K189="", "", MAX(0, K189 - (TODAY() - TODAY()))) -> 0 | O189: =IF(OR(K189="", J189=""), "", IF(K189<0, "Vencido", IF(K189>(J189/2), "Supere la mitad", "Bajo la mitad"))) -> Vencido | P189: CE-GC-0033 | Q189: 46036 | R189: =IF(OR(Q189="", L189=""), "", NETWORKDAYS(L189, Q189, FESTIVOS!A188:A242)) -> -34
A190: OTRO | B190: SIXTO ALFONSO PARAMO | C190: USUARIO DE SERVINTEGRAL | D190: COMUNICACIÓN DE ACTA MEDIANTE LA CUAL SE RESUELVE IMPUGNACIÓN FRENTE AL CASO MARIANO OSWALDO ROJAS ARANGO- C.C 94043507 Y SE REITERA EL DEBER DE ALLEGAR EL SOPORTE DE PAGO DE HONORARIOS A FAVOR DE LA JUNTA NACIONAL PARA EL TRÁMITE CORRESPONDIENTE | E190: 189 | F190: 46062 | G190: FALSE | H190: FALSE | J190: =IF(A190="INFORMACIÓN O DOCUMENTOS", 10, IF(A190="CONSULTA", 30, IF(A190="FACTURACIÓN Y COBROS", 15, IF(A190="VINCULACIÓN Y DESVINCULACIÓN", 15, IF(A190="NO ES DE NUESTRA COMPETENCIA", 5, IF(A190="OTRO", 15, "")))))) -> 15 | K190: =IF(AND(F190<>"", L190<>""), NETWORKDAYS(TODAY(), L190-1, FESTIVOS!A$1:A$55), "") -> -72 | L190: =IF(AND(F190<>"", J190<>""), WORKDAY(F190, J190, FESTIVOS!A$1:A$55), "") -> 46083 | M190: LAURA GIRALDO | N190: =IF(K190="", "", MAX(0, K190 - (TODAY() - TODAY()))) -> 0 | O190: =IF(OR(K190="", J190=""), "", IF(K190<0, "Vencido", IF(K190>(J190/2), "Supere la mitad", "Bajo la mitad"))) -> Vencido | P190: CE-GC-0033 | Q190: 46036 | R190: =IF(OR(Q190="", L190=""), "", NETWORKDAYS(L190, Q190, FESTIVOS!A189:A243)) -> -34
...

Sheet FESTIVOS
A1: 45658
A2: 45663
A3: 45740
A4: 45764
A5: 45765
A6: 45778
A7: 45810
A8: 45831
A9: 45838
A10: 45858
A11: 45876
A12: 45887
... A55: 46746
