Workbook

Sheet 2026
A1: TIPO DE SOLICITUD | B1: NOMBRE | C1: ENTIDAD | D1: ASUNTO | E1: RADICADO | F1: FECHA DE INGRESO DE LA SOLICITUD | G1: AREA RESPONSABLE | H1: TERMINO | I1: POSIBLES DIAS RESTANTES | J1: FECHA DE VENCIMIENTO | K1: QUEN RECIBIO | L1: ALERTA | M1: ALERTA 2 | N1: CONSECUTIVO | O1: FECHA DE SALIDA | P1: DIAS QUE LE SOBRARON
A2: OTRO | B2: MAYRA ARTUNDUAGA | C2: ESAC | D2: DESAFILIACIONES | E2: 1 | F2: 46024 | G2: COMERCIAL | H2: =IF(A2="INFORMACIÓN O DOCUMENTOS", 10, IF(A2="CONSULTA", 30, IF(A2="FACTURACIÓN Y COBROS", 15, IF(A2="VINCULACIÓN Y DESVINCULACIÓN", 15, IF(A2="NO ES DE NUESTRA COMPETENCIA", 5, IF(A2="OTRO", 15, "")))))) -> 15 | I2: =IF(AND(F2<>"", J2<>""), NETWORKDAYS(TODAY(), J2-1, FESTIVOS!A$1:A$55), "") -> -93 | J2: =IF(AND(F2<>"", H2<>""), WORKDAY(F2, H2, FESTIVOS!A$1:A$55), "") -> 46048 | K2: LAURA GIRALDO | L2: 0 | M2: =IF(OR(I2="", H2=""), "", IF(I2<0, "Vencido", IF(I2>(H2/2), "Supere la mitad", "Bajo la mitad"))) -> Vencido | N2: CE-GC-007 | O2: 46038 | P2: =IF(OR(O2="", J2=""), "", NETWORKDAYS(J2, O2, FESTIVOS!A1:A55)) -> -7
A3: OTRO | B3: MAYRA ARTUNDUAGA | C3: ESAC | D3: DESAFILIACIONES | E3: 2 | F3: 46024 | G3: COMERCIAL | H3: =IF(A3="INFORMACIÓN O DOCUMENTOS", 10, IF(A3="CONSULTA", 30, IF(A3="FACTURACIÓN Y COBROS", 15, IF(A3="VINCULACIÓN Y DESVINCULACIÓN", 15, IF(A3="NO ES DE NUESTRA COMPETENCIA", 5, IF(A3="OTRO", 15, "")))))) -> 15 | I3: =IF(AND(F3<>"", J3<>""), NETWORKDAYS(TODAY(), J3-1, FESTIVOS!A$1:A$55), "") -> -93 | J3: =IF(AND(F3<>"", H3<>""), WORKDAY(F3, H3, FESTIVOS!A$1:A$55), "") -> 46048 | K3: LAURA GIRALDO | L3: =IF(I3="", "", MAX(0, I3 - (TODAY() - TODAY()))) -> 0 | M3: =IF(OR(I3="", H3=""), "", IF(I3<0, "Vencido", IF(I3>(H3/2), "Supere la mitad", "Bajo la mitad"))) -> Vencido | N3: CE-GC-008 | O3: 46041 | P3: =IF(OR(O3="", J3=""), "", NETWORKDAYS(J3, O3, FESTIVOS!A2:A56)) -> -6
A4: OTRO | B4: CARLOS ALMERO VIDEL | C4: USUARIO | D4: COTIZACIÓN | E4: 3 | F4: 46027 | G4: COMERCIAL | H4: =IF(A4="INFORMACIÓN O DOCUMENTOS", 10, IF(A4="CONSULTA", 30, IF(A4="FACTURACIÓN Y COBROS", 15, IF(A4="VINCULACIÓN Y DESVINCULACIÓN", 15, IF(A4="NO ES DE NUESTRA COMPETENCIA", 5, IF(A4="OTRO", 15, "")))))) -> 15 | I4: =IF(AND(F4<>"", J4<>""), NETWORKDAYS(TODAY(), J4-1, FESTIVOS!A$1:A$55), "") -> -93 | J4: =IF(AND(F4<>"", H4<>""), WORKDAY(F4, H4, FESTIVOS!A$1:A$55), "") -> 46049 | K4: LAURA GIRALDO | L4: =IF(I4="", "", MAX(0, I4 - (TODAY() - TODAY()))) -> 0 | M4: =IF(OR(I4="", H4=""), "", IF(I4<0, "Vencido", IF(I4>(H4/2), "Supere la mitad", "Bajo la mitad"))) -> Vencido | N4: CE-GC-0011 | O4: 46029 | P4: =IF(OR(O4="", J4=""), "", NETWORKDAYS(J4, O4, FESTIVOS!A3:A57)) -> -14 | Q4: si salen en engativo sobraron
A5: OTRO | B5: MAYRA ARTUNDUAGA | C5: ESAC | D5: DESAFILIACIONES | E5: 4 | F5: 46027 | G5: COMERCIAL | H5: =IF(A5="INFORMACIÓN O DOCUMENTOS", 10, IF(A5="CONSULTA", 30, IF(A5="FACTURACIÓN Y COBROS", 15, IF(A5="VINCULACIÓN Y DESVINCULACIÓN", 15, IF(A5="NO ES DE NUESTRA COMPETENCIA", 5, IF(A5="OTRO", 15, "")))))) -> 15 | I5: =IF(AND(F5<>"", J5<>""), NETWORKDAYS(TODAY(), J5-1, FESTIVOS!A$1:A$55), "") -> -93 | J5: =IF(AND(F5<>"", H5<>""), WORKDAY(F5, H5, FESTIVOS!A$1:A$55), "") -> 46049 | K5: LAURA GIRALDO | L5: =IF(I5="", "", MAX(0, I5 - (TODAY() - TODAY()))) -> 0 | M5: =IF(OR(I5="", H5=""), "", IF(I5<0, "Vencido", IF(I5>(H5/2), "Supere la mitad", "Bajo la mitad"))) -> Vencido | N5: CE-GC-0010 | O5: 46038 | P5: =IF(OR(O5="", J5=""), "", NETWORKDAYS(J5, O5, FESTIVOS!A4:A58)) -> -8 | Q5: si salen positivos nos pasamos
A6: OTRO | B6: EMITIDO POR LA ALCALDIA | C6: ALCALDIA | D6: TRASLADO POR COMPETENCIA -MARIA MARGARITALOPEZ GOMEZ | E6: 5 | F6: 46028 | G6: COMERCIAL | H6: =IF(A6="INFORMACIÓN O DOCUMENTOS", 10, IF(A6="CONSULTA", 30, IF(A6="FACTURACIÓN Y COBROS", 15, IF(A6="VINCULACIÓN Y DESVINCULACIÓN", 15, IF(A6="NO ES DE NUESTRA COMPETENCIA", 5, IF(A6="OTRO", 15, "")))))) -> 15 | I6: =IF(AND(F6<>"", J6<>""), NETWORKDAYS(TODAY(), J6-1, FESTIVOS!A$1:A$55), "") -> -92 | J6: =IF(AND(F6<>"", H6<>""), WORKDAY(F6, H6, FESTIVOS!A$1:A$55), "") -> 46050 | K6: LAURA GIRALDO | L6: =IF(I6="", "", MAX(0, I6 - (TODAY() - TODAY()))) -> 0 | M6: =IF(OR(I6="", H6=""), "", IF(I6<0, "Vencido", IF(I6>(H6/2), "Supere la mitad", "Bajo la mitad"))) -> Vencido | N6: CE-GC-0055 | O6: 46038 | P6: =IF(OR(O6="", J6=""), "", NETWORKDAYS(J6, O6, FESTIVOS!A5:A59)) -> -9
A7: OTRO | B7: KARLA JOHANA LISCANO CORREA | C7: ALCALDIA | D7: ACTA DEL COMITÉ DE CONOCIMIENTO DE RIESGO | E7: 6 | F7: 46028 | G7: COMERCIAL | H7: =IF(A7="INFORMACIÓN O DOCUMENTOS", 10, IF(A7="CONSULTA", 30, IF(A7="FACTURACIÓN Y COBROS", 15, IF(A7="VINCULACIÓN Y DESVINCULACIÓN", 15, IF(A7="NO ES DE NUESTRA COMPETENCIA", 5, IF(A7="OTRO", 15, "")))))) -> 15 | I7: =IF(AND(F7<>"", J7<>""), NETWORKDAYS(TODAY(), J7-1, FESTIVOS!A$1:A$55), "") -> -92 | J7: =IF(AND(F7<>"", H7<>""), WORKDAY(F7, H7, FESTIVOS!A$1:A$55), "") -> 46050 | K7: LAURA GIRALDO | L7: =IF(I7="", "", MAX(0, I7 - (TODAY() - TODAY()))) -> 0 | M7: =IF(OR(I7="", H7=""), "", IF(I7<0, "Vencido", IF(I7>(H7/2), "Supere la mitad", "Bajo la mitad"))) -> Vencido | N7: NO REQUIERE RESPUESTA | P7: =IF(OR(O7="", J7=""), "", NETWORKDAYS(J7, O7, FESTIVOS!A6:A60))
A8: OTRO | B8: ESTHER JULIA GOMEZ | C8: USUARIO | D8: DERECHO DE PETICIÓN | E8: 7 | F8: 46028 | G8: COMERCIAL | H8: =IF(A8="INFORMACIÓN O DOCUMENTOS", 10, IF(A8="CONSULTA", 30, IF(A8="FACTURACIÓN Y COBROS", 15, IF(A8="VINCULACIÓN Y DESVINCULACIÓN", 15, IF(A8="NO ES DE NUESTRA COMPETENCIA", 5, IF(A8="OTRO", 15, "")))))) -> 15 | I8: =IF(AND(F8<>"", J8<>""), NETWORKDAYS(TODAY(), J8-1, FESTIVOS!A$1:A$55), "") -> -92 | J8: =IF(AND(F8<>"", H8<>""), WORKDAY(F8, H8, FESTIVOS!A$1:A$55), "") -> 46050 | K8: LAURA GIRALDO | L8: =IF(I8="", "", MAX(0, I8 - (TODAY() - TODAY()))) -> 0 | M8: =IF(OR(I8="", H8=""), "", IF(I8<0, "Vencido", IF(I8>(H8/2), "Supere la mitad", "Bajo la mitad"))) -> Vencido | N8: CE-GC-0113 | O8: 46050 | P8: =IF(OR(O8="", J8=""), "", NETWORKDAYS(J8, O8, FESTIVOS!A7:A61)) -> 1
A9: OTRO | B9: OMAR JOSE MAESTRE FELIZZOLA | C9: SUPER | D9: REMISIÓN MESA DE TRABAJO | E9: 8 | F9: 46028 | G9: JURÍDICA | H9: =IF(A9="INFORMACIÓN O DOCUMENTOS", 10, IF(A9="CONSULTA", 30, IF(A9="FACTURACIÓN Y COBROS", 15, IF(A9="VINCULACIÓN Y DESVINCULACIÓN", 15, IF(A9="NO ES DE NUESTRA COMPETENCIA", 5, IF(A9="OTRO", 15, "")))))) -> 15 | I9: =IF(AND(F9<>"", J9<>""), NETWORKDAYS(TODAY(), J9-1, FESTIVOS!A$1:A$55), "") -> -92 | J9: =IF(AND(F9<>"", H9<>""), WORKDAY(F9, H9, FESTIVOS!A$1:A$55), "") -> 46050 | K9: LAURA GIRALDO | L9: =IF(I9="", "", MAX(0, I9 - (TODAY() - TODAY()))) -> 0 | M9: =IF(OR(I9="", H9=""), "", IF(I9<0, "Vencido", IF(I9>(H9/2), "Supere la mitad", "Bajo la mitad"))) -> Vencido | P9: =IF(OR(O9="", J9=""), "", NETWORKDAYS(J9, O9, FESTIVOS!A8:A62))
A10: OTRO | B10: ADRIANA GUZMÁN BUITRAGO | C10: USUARIO DE SERVINTEGRAL | D10: DERECHO DE PETICIÓN | E10: 9 | F10: 46028 | G10: COMERCIAL | H10: =IF(A10="INFORMACIÓN O DOCUMENTOS", 10, IF(A10="CONSULTA", 30, IF(A10="FACTURACIÓN Y COBROS", 15, IF(A10="VINCULACIÓN Y DESVINCULACIÓN", 15, IF(A10="NO ES DE NUESTRA COMPETENCIA", 5, IF(A10="OTRO", 15, "")))))) -> 15 | I10: =IF(AND(F10<>"", J10<>""), NETWORKDAYS(TODAY(), J10-1, FESTIVOS!A$1:A$55), "") -> -92 | J10: =IF(AND(F10<>"", H10<>""), WORKDAY(F10, H10, FESTIVOS!A$1:A$55), "") -> 46050 | K10: LAURA GIRALDO | L10: =IF(I10="", "", MAX(0, I10 - (TODAY() - TODAY()))) -> 0 | M10: =IF(OR(I10="", H10=""), "", IF(I10<0, "Vencido", IF(I10>(H10/2), "Supere la mitad", "Bajo la mitad"))) -> Vencido | N10: CE-GC-0065 | O10: 46041 | P10: =IF(OR(O10="", J10=""), "", NETWORKDAYS(J10, O10, FESTIVOS!A9:A63)) -> -8
A11: OTRO | B11: GINA PAOLA RIVERA CHACON | C11: USUARIO DE SERVINTEGRAL | D11: RESPUESTA DE VINCULACIÓN | E11: 10 | F11: 46029 | G11: COMERCIAL | H11: =IF(A11="INFORMACIÓN O DOCUMENTOS", 10, IF(A11="CONSULTA", 30, IF(A11="FACTURACIÓN Y COBROS", 15, IF(A11="VINCULACIÓN Y DESVINCULACIÓN", 15, IF(A11="NO ES DE NUESTRA COMPETENCIA", 5, IF(A11="OTRO", 15, "")))))) -> 15 | I11: =IF(AND(F11<>"", J11<>""), NETWORKDAYS(TODAY(), J11-1, FESTIVOS!A$1:A$55), "") -> -91 | J11: =IF(AND(F11<>"", H11<>""), WORKDAY(F11, H11, FESTIVOS!A$1:A$55), "") -> 46051 | K11: LAURA GIRALDO | L11: =IF(I11="", "", MAX(0, I11 - (TODAY() - TODAY()))) -> 0 | M11: =IF(OR(I11="", H11=""), "", IF(I11<0, "Vencido", IF(I11>(H11/2), "Supere la mitad", "Bajo la mitad"))) -> Vencido | N11: CE-GC-0012 | O11: 46037 | P11: =IF(OR(O11="", J11=""), "", NETWORKDAYS(J11, O11, FESTIVOS!A10:A64)) -> -11
A12: OTRO | B12: EQUIPO DE VERIFICACIÓN | C12: USUARIO DE SERVINTEGRAL | D12: ACTUALIZACIÓN DE INFORMACIÓN | E12: 11 | F12: 46029 | G12: JURÍDICA | H12: =IF(A12="INFORMACIÓN O DOCUMENTOS", 10, IF(A12="CONSULTA", 30, IF(A12="FACTURACIÓN Y COBROS", 15, IF(A12="VINCULACIÓN Y DESVINCULACIÓN", 15, IF(A12="NO ES DE NUESTRA COMPETENCIA", 5, IF(A12="OTRO", 15, "")))))) -> 15 | I12: =IF(AND(F12<>"", J12<>""), NETWORKDAYS(TODAY(), J12-1, FESTIVOS!A$1:A$55), "") -> -91 | J12: =IF(AND(F12<>"", H12<>""), WORKDAY(F12, H12, FESTIVOS!A$1:A$55), "") -> 46051 | K12: LAURA GIRALDO | L12: =IF(I12="", "", MAX(0, I12 - (TODAY() - TODAY()))) -> 0 | M12: =IF(OR(I12="", H12=""), "", IF(I12<0, "Vencido", IF(I12>(H12/2), "Supere la mitad", "Bajo la mitad"))) -> Vencido | P12: =IF(OR(O12="", J12=""), "", NETWORKDAYS(J12, O12, FESTIVOS!A11:A65))
A13: OTRO | B13: MARIA GLORIA CUELLAR LOZANO | C13: USUARIO DE SERVINTEGRAL | D13: INMUEBLE DESOCUPADO | E13: 12 | F13: 46030 | G13: COMERCIAL | H13: =IF(A13="INFORMACIÓN O DOCUMENTOS", 10, IF(A13="CONSULTA", 30, IF(A13="FACTURACIÓN Y COBROS", 15, IF(A13="VINCULACIÓN Y DESVINCULACIÓN", 15, IF(A13="NO ES DE NUESTRA COMPETENCIA", 5, IF(A13="OTRO", 15, "")))))) -> 15 | I13: =IF(AND(F13<>"", J13<>""), NETWORKDAYS(TODAY(), J13-1, FESTIVOS!A$1:A$55), "") -> -90 | J13: =IF(AND(F13<>"", H13<>""), WORKDAY(F13, H13, FESTIVOS!A$1:A$55), "") -> 46052 | K13: LAURA GIRALDO | L13: =IF(I13="", "", MAX(0, I13 - (TODAY() - TODAY()))) -> 0 | M13: =IF(OR(I13="", H13=""), "", IF(I13<0, "Vencido", IF(I13>(H13/2), "Supere la mitad", "Bajo la mitad"))) -> Vencido | N13: CE-GC-0033 | O13: 46036 | P13: =IF(OR(O13="", J13=""), "", NETWORKDAYS(J13, O13, FESTIVOS!A12:A66)) -> -13
A14: OTRO | B14: DIANA MARCELA PERDOMO BELTRÁN | C14: SUPER | D14: Respuesta al radicado de entrada SSPD No. 20255294845332 de fecha 20 de noviembre de 2025 - Respuesta a solicitud con radicado interno 2529 del 4 de noviembre de 2025. “Radicado CE-GT-2420 (Respuesta a Radicado No. 2437 del 20 de octubre de 2025.Requerimiento Ordinario No. 49 - 3458)” | E14: 13 | F14: 46030 | G14: JURÍDICA | H14: =IF(A14="INFORMACIÓN O DOCUMENTOS", 10, IF(A14="CONSULTA", 30, IF(A14="FACTURACIÓN Y COBROS", 15, IF(A14="VINCULACIÓN Y DESVINCULACIÓN", 15, IF(A14="NO ES DE NUESTRA COMPETENCIA", 5, IF(A14="OTRO", 15, "")))))) -> 15 | I14: =IF(AND(F14<>"", J14<>""), NETWORKDAYS(TODAY(), J14-1, FESTIVOS!A$1:A$55), "") -> -90 | J14: =IF(AND(F14<>"", H14<>""), WORKDAY(F14, H14, FESTIVOS!A$1:A$55), "") -> 46052 | K14: LAURA GIRALDO | L14: =IF(I14="", "", MAX(0, I14 - (TODAY() - TODAY()))) -> 0 | M14: =IF(OR(I14="", H14=""), "", IF(I14<0, "Vencido", IF(I14>(H14/2), "Supere la mitad", "Bajo la mitad"))) -> Vencido | N14: CE-GC-0033 | O14: 46036 | P14: =IF(OR(O14="", J14=""), "", NETWORKDAYS(J14, O14, FESTIVOS!A13:A67)) -> -13
A15: OTRO | B15: ISMAEL SILVA ALVAREZ | C15: GAS CAQUETA | D15: SOLICITUD DE CERTIFICADO | E15: 14 | F15: 46030 | G15: COMERCIAL | H15: =IF(A15="INFORMACIÓN O DOCUMENTOS", 10, IF(A15="CONSULTA", 30, IF(A15="FACTURACIÓN Y COBROS", 15, IF(A15="VINCULACIÓN Y DESVINCULACIÓN", 15, IF(A15="NO ES DE NUESTRA COMPETENCIA", 5, IF(A15="OTRO", 15, "")))))) -> 15 | I15: =IF(AND(F15<>"", J15<>""), NETWORKDAYS(TODAY(), J15-1, FESTIVOS!A$1:A$55), "") -> -90 | J15: =IF(AND(F15<>"", H15<>""), WORKDAY(F15, H15, FESTIVOS!A$1:A$55), "") -> 46052 | K15: LAURA GIRALDO | L15: =IF(I15="", "", MAX(0, I15 - (TODAY() - TODAY()))) -> 0 | M15: =IF(OR(I15="", H15=""), "", IF(I15<0, "Vencido", IF(I15>(H15/2), "Supere la mitad", "Bajo la mitad"))) -> Vencido | N15: CE-GC-0014 | O15: 46035 | P15: =IF(OR(O15="", J15=""), "", NETWORKDAYS(J15, O15, FESTIVOS!A14:A68)) -> -14
A16: OTRO | B16: LORENA CASTAÑO | C16: SAMAMB | D16: CARACTERIZACIÓN | E16: 15 | F16: 46030 | G16: RESIDUOS | H16: =IF(A16="INFORMACIÓN O DOCUMENTOS", 10, IF(A16="CONSULTA", 30, IF(A16="FACTURACIÓN Y COBROS", 15, IF(A16="VINCULACIÓN Y DESVINCULACIÓN", 15, IF(A16="NO ES DE NUESTRA COMPETENCIA", 5, IF(A16="OTRO", 15, "")))))) -> 15 | I16: =IF(AND(F16<>"", J16<>""), NETWORKDAYS(TODAY(), J16-1, FESTIVOS!A$1:A$55), "") -> -90 | J16: =IF(AND(F16<>"", H16<>""), WORKDAY(F16, H16, FESTIVOS!A$1:A$55), "") -> 46052 | K16: LAURA GIRALDO | L16: =IF(I16="", "", MAX(0, I16 - (TODAY() - TODAY()))) -> 0 | M16: =IF(OR(I16="", H16=""), "", IF(I16<0, "Vencido", IF(I16>(H16/2), "Supere la mitad", "Bajo la mitad"))) -> Vencido | N16: NO REQUIERE RESPUESTA | P16: =IF(OR(O16="", J16=""), "", NETWORKDAYS(J16, O16, FESTIVOS!A15:A69))
A17: OTRO | B17: LORENA CASTAÑO | C17: SAMAMB | D17: PROPUESTA | E17: 16 | F17: 46030 | G17: COMERCIAL | H17: =IF(A17="INFORMACIÓN O DOCUMENTOS", 10, IF(A17="CONSULTA", 30, IF(A17="FACTURACIÓN Y COBROS", 15, IF(A17="VINCULACIÓN Y DESVINCULACIÓN", 15, IF(A17="NO ES DE NUESTRA COMPETENCIA", 5, IF(A17="OTRO", 15, "")))))) -> 15 | I17: =IF(AND(F17<>"", J17<>""), NETWORKDAYS(TODAY(), J17-1, FESTIVOS!A$1:A$55), "") -> -90 | J17: =IF(AND(F17<>"", H17<>""), WORKDAY(F17, H17, FESTIVOS!A$1:A$55), "") -> 46052 | K17: LAURA GIRALDO | L17: =IF(I17="", "", MAX(0, I17 - (TODAY() - TODAY()))) -> 0 | M17: =IF(OR(I17="", H17=""), "", IF(I17<0, "Vencido", IF(I17>(H17/2), "Supere la mitad", "Bajo la mitad"))) -> Vencido | N17: NO REQUIERE RESPUESTA | P17: =IF(OR(O17="", J17=""), "", NETWORKDAYS(J17, O17, FESTIVOS!A16:A70))
A18: OTRO | B18: FREDY HERNAN TEJADA | C18: ELECTROCAQUETA | D18: Respuesta a oficio CE-GC-0002 del 05-01-2026 con Rad interno No 2026-1-1-75 del 06-01-2026 | E18: 17 | F18: 46030 | G18: COMERCIAL | H18: =IF(A18="INFORMACIÓN O DOCUMENTOS", 10, IF(A18="CONSULTA", 30, IF(A18="FACTURACIÓN Y COBROS", 15, IF(A18="VINCULACIÓN Y DESVINCULACIÓN", 15, IF(A18="NO ES DE NUESTRA COMPETENCIA", 5, IF(A18="OTRO", 15, "")))))) -> 15 | I18: =IF(AND(F18<>"", J18<>""), NETWORKDAYS(TODAY(), J18-1, FESTIVOS!A$1:A$55), "") -> -90 | J18: =IF(AND(F18<>"", H18<>""), WORKDAY(F18, H18, FESTIVOS!A$1:A$55), "") -> 46052 | K18: LAURA GIRALDO | L18: =IF(I18="", "", MAX(0, I18 - (TODAY() - TODAY()))) -> 0 | M18: =IF(OR(I18="", H18=""), "", IF(I18<0, "Vencido", IF(I18>(H18/2), "Supere la mitad", "Bajo la mitad"))) -> Vencido | N18: NO REQUIERE RESPUESTA | P18: =IF(OR(O18="", J18=""), "", NETWORKDAYS(J18, O18, FESTIVOS!A17:A71))
A19: OTRO | B19: FREDY HERNAN TEJADA | C19: ELECTROCAQUETA | D19: Respuesta a oficio CE-GC-0001 del 05-1-2026 con Rad interno No 2026-1-1-74 del 06-01-2026 | E19: 18 | F19: 46031 | G19: COMERCIAL | H19: =IF(A19="INFORMACIÓN O DOCUMENTOS", 10, IF(A19="CONSULTA", 30, IF(A19="FACTURACIÓN Y COBROS", 15, IF(A19="VINCULACIÓN Y DESVINCULACIÓN", 15, IF(A19="NO ES DE NUESTRA COMPETENCIA", 5, IF(A19="OTRO", 15, "")))))) -> 15 | I19: =IF(AND(F19<>"", J19<>""), NETWORKDAYS(TODAY(), J19-1, FESTIVOS!A$1:A$55), "") -> -88 | J19: =IF(AND(F19<>"", H19<>""), WORKDAY(F19, H19, FESTIVOS!A$1:A$55), "") -> 46055 | K19: LAURA GIRALDO | L19: =IF(I19="", "", MAX(0, I19 - (TODAY() - TODAY()))) -> 0 | M19: =IF(OR(I19="", H19=""), "", IF(I19<0, "Vencido", IF(I19>(H19/2), "Supere la mitad", "Bajo la mitad"))) -> Vencido | N19: NO REQUIERE RESPUESTA | P19: =IF(OR(O19="", J19=""), "", NETWORKDAYS(J19, O19, FESTIVOS!A18:A72))
A20: OTRO | B20: LUZ ELIANA TOBON MUÑOZ | C20: USUARIO DE SERVINTEGRAL | D20: SOLICITD DE ESCOMBROS | E20: 19 | F20: 46031 | G20: COMERCIAL | H20: =IF(A20="INFORMACIÓN O DOCUMENTOS", 10, IF(A20="CONSULTA", 30, IF(A20="FACTURACIÓN Y COBROS", 15, IF(A20="VINCULACIÓN Y DESVINCULACIÓN", 15, IF(A20="NO ES DE NUESTRA COMPETENCIA", 5, IF(A20="OTRO", 15, "")))))) -> 15 | I20: =IF(AND(F20<>"", J20<>""), NETWORKDAYS(TODAY(), J20-1, FESTIVOS!A$1:A$55), "") -> -88 | J20: =IF(AND(F20<>"", H20<>""), WORKDAY(F20, H20, FESTIVOS!A$1:A$55), "") -> 46055 | K20: LAURA GIRALDO | L20: =IF(I20="", "", MAX(0, I20 - (TODAY() - TODAY()))) -> 0 | M20: =IF(OR(I20="", H20=""), "", IF(I20<0, "Vencido", IF(I20>(H20/2), "Supere la mitad", "Bajo la mitad"))) -> Vencido | N20: CE-GC-0073 | O20: 46043 | P20: =IF(OR(O20="", J20=""), "", NETWORKDAYS(J20, O20, FESTIVOS!A19:A73)) -> -9
A21: OTRO | B21: NANCY BOHORQUEZ | C21: USUARIO DE SERVINTEGRAL | D21: SOLICITD DE DESCUENTO EN LA DEUDA DE ASEO | E21: 20 | F21: 46035 | G21: COMERCIAL | H21: =IF(A21="INFORMACIÓN O DOCUMENTOS", 10, IF(A21="CONSULTA", 30, IF(A21="FACTURACIÓN Y COBROS", 15, IF(A21="VINCULACIÓN Y DESVINCULACIÓN", 15, IF(A21="NO ES DE NUESTRA COMPETENCIA", 5, IF(A21="OTRO", 15, "")))))) -> 15 | I21: =IF(AND(F21<>"", J21<>""), NETWORKDAYS(TODAY(), J21-1, FESTIVOS!A$1:A$55), "") -> -88 | J21: =IF(AND(F21<>"", H21<>""), WORKDAY(F21, H21, FESTIVOS!A$1:A$55), "") -> 46056 | K21: LAURA GIRALDO | L21: =IF(I21="", "", MAX(0, I21 - (TODAY() - TODAY()))) -> 0 | N21: CE-GC-0050 | O21: 46037 | P21: =IF(OR(O21="", J21=""), "", NETWORKDAYS(J21, O21, FESTIVOS!A20:A74)) -> -14
A22: OTRO | B22: EMA | C22: USUARIO DE SERVINTEGRAL | D22: REFERENCIAS PERSONALES | E22: 21 | F22: 46035 | G22: TALENTO HUMANO | H22: =IF(A22="INFORMACIÓN O DOCUMENTOS", 10, IF(A22="CONSULTA", 30, IF(A22="FACTURACIÓN Y COBROS", 15, IF(A22="VINCULACIÓN Y DESVINCULACIÓN", 15, IF(A22="NO ES DE NUESTRA COMPETENCIA", 5, IF(A22="OTRO", 15, "")))))) -> 15 | I22: =IF(AND(F22<>"", J22<>""), NETWORKDAYS(TODAY(), J22-1, FESTIVOS!A$1:A$55), "") -> -88 | J22: =IF(AND(F22<>"", H22<>""), WORKDAY(F22, H22, FESTIVOS!A$1:A$55), "") -> 46056 | K22: LAURA GIRALDO | L22: =IF(I22="", "", MAX(0, I22 - (TODAY() - TODAY()))) -> 0 | M22: =IF(OR(I22="", H22=""), "", IF(I22<0, "Vencido", IF(I22>(H22/2), "Supere la mitad", "Bajo la mitad"))) -> Vencido | N22: NO REQUIERE RESPUESTA | P22: =IF(OR(O22="", J22=""), "", NETWORKDAYS(J22, O22, FESTIVOS!A21:A75))
A23: OTRO | B23: LEONOR RODRIGUEZ CELIS | C23: USUARIO DE SERVINTEGRAL | D23: AGRADECIMIENTO | E23: 22 | F23: 46035 | G23: RESIDUOS | H23: =IF(A23="INFORMACIÓN O DOCUMENTOS", 10, IF(A23="CONSULTA", 30, IF(A23="FACTURACIÓN Y COBROS", 15, IF(A23="VINCULACIÓN Y DESVINCULACIÓN", 15, IF(A23="NO ES DE NUESTRA COMPETENCIA", 5, IF(A23="OTRO", 15, "")))))) -> 15 | I23: =IF(AND(F23<>"", J23<>""), NETWORKDAYS(TODAY(), J23-1, FESTIVOS!A$1:A$55), "") -> -88 | J23: =IF(AND(F23<>"", H23<>""), WORKDAY(F23, H23, FESTIVOS!A$1:A$55), "") -> 46056 | K23: LAURA GIRALDO | L23: =IF(I23="", "", MAX(0, I23 - (TODAY() - TODAY()))) -> 0 | M23: =IF(OR(I23="", H23=""), "", IF(I23<0, "Vencido", IF(I23>(H23/2), "Supere la mitad", "Bajo la mitad"))) -> Vencido | N23: CE-GC-0033 | O23: 46036 | P23: =IF(OR(O23="", J23=""), "", NETWORKDAYS(J23, O23, FESTIVOS!A22:A76)) -> -15
A24: OTRO | B24: YULIANA ESCOBAR | C24: ESAC | D24: NOTIFICACIÓN PERSONAL | E24: 23 | F24: 46035 | G24: COMERCIAL | H24: =IF(A24="INFORMACIÓN O DOCUMENTOS", 10, IF(A24="CONSULTA", 30, IF(A24="FACTURACIÓN Y COBROS", 15, IF(A24="VINCULACIÓN Y DESVINCULACIÓN", 15, IF(A24="NO ES DE NUESTRA COMPETENCIA", 5, IF(A24="OTRO", 15, "")))))) -> 15 | I24: =IF(AND(F24<>"", J24<>""), NETWORKDAYS(TODAY(), J24-1, FESTIVOS!A$1:A$55), "") -> -88 | J24: =IF(AND(F24<>"", H24<>""), WORKDAY(F24, H24, FESTIVOS!A$1:A$55), "") -> 46056 | K24: LAURA GIRALDO | L24: =IF(I24="", "", MAX(0, I24 - (TODAY() - TODAY()))) -> 0 | M24: =IF(OR(I24="", H24=""), "", IF(I24<0, "Vencido", IF(I24>(H24/2), "Supere la mitad", "Bajo la mitad"))) -> Vencido | N24: CE-GC-0033 | O24: 46036 | P24: =IF(OR(O24="", J24=""), "", NETWORKDAYS(J24, O24, FESTIVOS!A23:A77)) -> -15
A25: OTRO | B25: YULIANA ESCOBAR | C25: ESAC | D25: NOTIFICACIÓN PERSONAL | E25: 24 | F25: 46035 | G25: COMERCIAL | H25: =IF(A25="INFORMACIÓN O DOCUMENTOS", 10, IF(A25="CONSULTA", 30, IF(A25="FACTURACIÓN Y COBROS", 15, IF(A25="VINCULACIÓN Y DESVINCULACIÓN", 15, IF(A25="NO ES DE NUESTRA COMPETENCIA", 5, IF(A25="OTRO", 15, "")))))) -> 15 | I25: =IF(AND(F25<>"", J25<>""), NETWORKDAYS(TODAY(), J25-1, FESTIVOS!A$1:A$55), "") -> -88 | J25: =IF(AND(F25<>"", H25<>""), WORKDAY(F25, H25, FESTIVOS!A$1:A$55), "") -> 46056 | K25: LAURA GIRALDO | L25: =IF(I25="", "", MAX(0, I25 - (TODAY() - TODAY()))) -> 0 | M25: =IF(OR(I25="", H25=""), "", IF(I25<0, "Vencido", IF(I25>(H25/2), "Supere la mitad", "Bajo la mitad"))) -> Vencido | N25: CE-GC-0033 | O25: 46036 | P25: =IF(OR(O25="", J25=""), "", NETWORKDAYS(J25, O25, FESTIVOS!A24:A78)) -> -15
A26: OTRO | B26: YULIANA ESCOBAR | C26: ESAC | D26: NOTIFICACIÓN PERSONAL | E26: 25 | F26: 46035 | G26: COMERCIAL | H26: =IF(A26="INFORMACIÓN O DOCUMENTOS", 10, IF(A26="CONSULTA", 30, IF(A26="FACTURACIÓN Y COBROS", 15, IF(A26="VINCULACIÓN Y DESVINCULACIÓN", 15, IF(A26="NO ES DE NUESTRA COMPETENCIA", 5, IF(A26="OTRO", 15, "")))))) -> 15 | I26: =IF(AND(F26<>"", J26<>""), NETWORKDAYS(TODAY(), J26-1, FESTIVOS!A$1:A$55), "") -> -88 | J26: =IF(AND(F26<>"", H26<>""), WORKDAY(F26, H26, FESTIVOS!A$1:A$55), "") -> 46056 | K26: LAURA GIRALDO | L26: =IF(I26="", "", MAX(0, I26 - (TODAY() - TODAY()))) -> 0 | M26: =IF(OR(I26="", H26=""), "", IF(I26<0, "Vencido", IF(I26>(H26/2), "Supere la mitad", "Bajo la mitad"))) -> Vencido | N26: CE-GC-0033 | O26: 46036 | P26: =IF(OR(O26="", J26=""), "", NETWORKDAYS(J26, O26, FESTIVOS!A25:A79)) -> -15
A27: OTRO | B27: YULIANA ESCOBAR | C27: ESAC | D27: NOTIFICACIÓN PERSONAL | E27: 26 | F27: 46035 | G27: COMERCIAL | H27: =IF(A27="INFORMACIÓN O DOCUMENTOS", 10, IF(A27="CONSULTA", 30, IF(A27="FACTURACIÓN Y COBROS", 15, IF(A27="VINCULACIÓN Y DESVINCULACIÓN", 15, IF(A27="NO ES DE NUESTRA COMPETENCIA", 5, IF(A27="OTRO", 15, "")))))) -> 15 | I27: =IF(AND(F27<>"", J27<>""), NETWORKDAYS(TODAY(), J27-1, FESTIVOS!A$1:A$55), "") -> -88 | J27: =IF(AND(F27<>"", H27<>""), WORKDAY(F27, H27, FESTIVOS!A$1:A$55), "") -> 46056 | K27: LAURA GIRALDO | L27: =IF(I27="", "", MAX(0, I27 - (TODAY() - TODAY()))) -> 0 | M27: =IF(OR(I27="", H27=""), "", IF(I27<0, "Vencido", IF(I27>(H27/2), "Supere la mitad", "Bajo la mitad"))) -> Vencido | N27: CE-GC-0033 | O27: 46036 | P27: =IF(OR(O27="", J27=""), "", NETWORKDAYS(J27, O27, FESTIVOS!A26:A80)) -> -15
A28: OTRO | B28: YULIANA ESCOBAR | C28: ESAC | D28: NOTIFICACIÓN PERSONAL | E28: 27 | F28: 46035 | G28: COMERCIAL | H28: =IF(A28="INFORMACIÓN O DOCUMENTOS", 10, IF(A28="CONSULTA", 30, IF(A28="FACTURACIÓN Y COBROS", 15, IF(A28="VINCULACIÓN Y DESVINCULACIÓN", 15, IF(A28="NO ES DE NUESTRA COMPETENCIA", 5, IF(A28="OTRO", 15, "")))))) -> 15 | I28: =IF(AND(F28<>"", J28<>""), NETWORKDAYS(TODAY(), J28-1, FESTIVOS!A$1:A$55), "") -> -88 | J28: =IF(AND(F28<>"", H28<>""), WORKDAY(F28, H28, FESTIVOS!A$1:A$55), "") -> 46056 | K28: LAURA GIRALDO | L28: =IF(I28="", "", MAX(0, I28 - (TODAY() - TODAY()))) -> 0 | M28: =IF(OR(I28="", H28=""), "", IF(I28<0, "Vencido", IF(I28>(H28/2), "Supere la mitad", "Bajo la mitad"))) -> Vencido | N28: CE-GC-0033 | O28: 46036 | P28: =IF(OR(O28="", J28=""), "", NETWORKDAYS(J28, O28, FESTIVOS!A27:A81)) -> -15
A29: OTRO | B29: WILLIAM EDMUNDO PIEDRAHITA MAYA | C29: CORPOAMAZONIA | D29: TRASLADO POR COMPETENCIA | E29: 28 | F29: 46035 | G29: COMERCIAL | H29: =IF(A29="INFORMACIÓN O DOCUMENTOS", 10, IF(A29="CONSULTA", 30, IF(A29="FACTURACIÓN Y COBROS", 15, IF(A29="VINCULACIÓN Y DESVINCULACIÓN", 15, IF(A29="NO ES DE NUESTRA COMPETENCIA", 5, IF(A29="OTRO", 15, "")))))) -> 15 | I29: =IF(AND(F29<>"", J29<>""), NETWORKDAYS(TODAY(), J29-1, FESTIVOS!A$1:A$55), "") -> -88 | J29: =IF(AND(F29<>"", H29<>""), WORKDAY(F29, H29, FESTIVOS!A$1:A$55), "") -> 46056 | K29: LAURA GIRALDO | L29: =IF(I29="", "", MAX(0, I29 - (TODAY() - TODAY()))) -> 0 | M29: =IF(OR(I29="", H29=""), "", IF(I29<0, "Vencido", IF(I29>(H29/2), "Supere la mitad", "Bajo la mitad"))) -> Vencido | N29: CE-GC-0033 | O29: 46036 | P29: =IF(OR(O29="", J29=""), "", NETWORKDAYS(J29, O29, FESTIVOS!A28:A82)) -> -15
A30: OTRO | B30: LUIS MANUEL ESPINOSA CALDERON | C30: ALCALDIA | D30: SOLICITUD DE INFORMACIÓN PARA LIQUIDAR EL CONCURSO ECONOMICO | E30: 29 | F30: 46036 | G30: COMERCIAL | H30: =IF(A30="INFORMACIÓN O DOCUMENTOS", 10, IF(A30="CONSULTA", 30, IF(A30="FACTURACIÓN Y COBROS", 15, IF(A30="VINCULACIÓN Y DESVINCULACIÓN", 15, IF(A30="NO ES DE NUESTRA COMPETENCIA", 5, IF(A30="OTRO", 15, "")))))) -> 15 | I30: =IF(AND(F30<>"", J30<>""), NETWORKDAYS(TODAY(), J30-1, FESTIVOS!A$1:A$55), "") -> -87 | J30: =IF(AND(F30<>"", H30<>""), WORKDAY(F30, H30, FESTIVOS!A$1:A$55), "") -> 46057 | K30: LAURA GIRALDO | L30: =IF(I30="", "", MAX(0, I30 - (TODAY() - TODAY()))) -> 0 | M30: =IF(OR(I30="", H30=""), "", IF(I30<0, "Vencido", IF(I30>(H30/2), "Supere la mitad", "Bajo la mitad"))) -> Vencido | N30: CE-GC-0033 | O30: 46036 | P30: =IF(OR(O30="", J30=""), "", NETWORKDAYS(J30, O30, FESTIVOS!A29:A83)) -> -16
A31: OTRO | B31: Javier Hernán Puyo Plazas | C31: MINESTERIO DE TRABAJO | D31: Derecho de Petición fechado el día 23/12/2025 | E31: 30 | F31: 46036 | G31: TALENTO HUMANO | H31: =IF(A31="INFORMACIÓN O DOCUMENTOS", 10, IF(A31="CONSULTA", 30, IF(A31="FACTURACIÓN Y COBROS", 15, IF(A31="VINCULACIÓN Y DESVINCULACIÓN", 15, IF(A31="NO ES DE NUESTRA COMPETENCIA", 5, IF(A31="OTRO", 15, "")))))) -> 15 | I31: =IF(AND(F31<>"", J31<>""), NETWORKDAYS(TODAY(), J31-1, FESTIVOS!A$1:A$55), "") -> -87 | J31: =IF(AND(F31<>"", H31<>""), WORKDAY(F31, H31, FESTIVOS!A$1:A$55), "") -> 46057 | K31: LAURA GIRALDO | L31: =IF(I31="", "", MAX(0, I31 - (TODAY() - TODAY()))) -> 0 | M31: =IF(OR(I31="", H31=""), "", IF(I31<0, "Vencido", IF(I31>(H31/2), "Supere la mitad", "Bajo la mitad"))) -> Vencido | N31: CE-GC-0033 | O31: 46036 | P31: =IF(OR(O31="", J31=""), "", NETWORKDAYS(J31, O31, FESTIVOS!A30:A84)) -> -16
A32: OTRO | B32: LUIS ZAPATA OROZCO | C32: USUARIO DE SERVINTEGRAL | D32: SOLICITUD DE 1 LETRERO | E32: 31 | F32: 46036 | G32: COMERCIAL | H32: =IF(A32="INFORMACIÓN O DOCUMENTOS", 10, IF(A32="CONSULTA", 30, IF(A32="FACTURACIÓN Y COBROS", 15, IF(A32="VINCULACIÓN Y DESVINCULACIÓN", 15, IF(A32="NO ES DE NUESTRA COMPETENCIA", 5, IF(A32="OTRO", 15, "")))))) -> 15 | I32: =IF(AND(F32<>"", J32<>""), NETWORKDAYS(TODAY(), J32-1, FESTIVOS!A$1:A$55), "") -> -87 | J32: =IF(AND(F32<>"", H32<>""), WORKDAY(F32, H32, FESTIVOS!A$1:A$55), "") -> 46057 | K32: LAURA GIRALDO | L32: =IF(I32="", "", MAX(0, I32 - (TODAY() - TODAY()))) -> 0 | M32: =IF(OR(I32="", H32=""), "", IF(I32<0, "Vencido", IF(I32>(H32/2), "Supere la mitad", "Bajo la mitad"))) -> Vencido | N32: CE-GC-0033 | O32: 46036 | P32: =IF(OR(O32="", J32=""), "", NETWORKDAYS(J32, O32, FESTIVOS!A31:A85)) -> -16
A33: OTRO | B33: CLAUDIA TOVAR | C33: USUARIO DE SERVINTEGRAL | D33: VINCULACIÓN DIRECTA | E33: 32 | F33: 46036 | G33: COMERCIAL | H33: =IF(A33="INFORMACIÓN O DOCUMENTOS", 10, IF(A33="CONSULTA", 30, IF(A33="FACTURACIÓN Y COBROS", 15, IF(A33="VINCULACIÓN Y DESVINCULACIÓN", 15, IF(A33="NO ES DE NUESTRA COMPETENCIA", 5, IF(A33="OTRO", 15, "")))))) -> 15 | I33: =IF(AND(F33<>"", J33<>""), NETWORKDAYS(TODAY(), J33-1, FESTIVOS!A$1:A$55), "") -> -87 | J33: =IF(AND(F33<>"", H33<>""), WORKDAY(F33, H33, FESTIVOS!A$1:A$55), "") -> 46057 | K33: LAURA GIRALDO | L33: =IF(I33="", "", MAX(0, I33 - (TODAY() - TODAY()))) -> 0 | M33: =IF(OR(I33="", H33=""), "", IF(I33<0, "Vencido", IF(I33>(H33/2), "Supere la mitad", "Bajo la mitad"))) -> Vencido | N33: CE-GC-0033 | O33: 46036 | P33: =IF(OR(O33="", J33=""), "", NETWORKDAYS(J33, O33, FESTIVOS!A32:A86)) -> -16
A34: OTRO | B34: MARIA IRAIDES HERRERA GAITAN | C34: USUARIO DE SERVINTEGRAL | D34: VINCULACIÓN DIRECTA | E34: 33 | F34: 46036 | G34: COMERCIAL | H34: =IF(A34="INFORMACIÓN O DOCUMENTOS", 10, IF(A34="CONSULTA", 30, IF(A34="FACTURACIÓN Y COBROS", 15, IF(A34="VINCULACIÓN Y DESVINCULACIÓN", 15, IF(A34="NO ES DE NUESTRA COMPETENCIA", 5, IF(A34="OTRO", 15, "")))))) -> 15 | I34: =IF(AND(F34<>"", J34<>""), NETWORKDAYS(TODAY(), J34-1, FESTIVOS!A$1:A$55), "") -> -87 | J34: =IF(AND(F34<>"", H34<>""), WORKDAY(F34, H34, FESTIVOS!A$1:A$55), "") -> 46057 | K34: LAURA GIRALDO | L34: =IF(I34="", "", MAX(0, I34 - (TODAY() - TODAY()))) -> 0 | M34: =IF(OR(I34="", H34=""), "", IF(I34<0, "Vencido", IF(I34>(H34/2), "Supere la mitad", "Bajo la mitad"))) -> Vencido | N34: CE-GC-0033 | O34: 46036 | P34: =IF(OR(O34="", J34=""), "", NETWORKDAYS(J34, O34, FESTIVOS!A33:A87)) -> -16
... A186: OTRO | B186: CHRISTYAM CAMILO SALAZAR ROJAS | C186: ALCALDIA | D186: APOYO INSTITUCIONAL | E186: 185 | F186: 46062 | G186: COMERCIAL | H186: =IF(A186="INFORMACIÓN O DOCUMENTOS", 10, IF(A186="CONSULTA", 30, IF(A186="FACTURACIÓN Y COBROS", 15, IF(A186="VINCULACIÓN Y DESVINCULACIÓN", 15, IF(A186="NO ES DE NUESTRA COMPETENCIA", 5, IF(A186="OTRO", 15, "")))))) -> 15 | I186: =IF(AND(F186<>"", J186<>""), NETWORKDAYS(TODAY(), J186-1, FESTIVOS!A$1:A$55), "") -> -68 | J186: =IF(AND(F186<>"", H186<>""), WORKDAY(F186, H186, FESTIVOS!A$1:A$55), "") -> 46083 | K186: LAURA GIRALDO | L186: =IF(I186="", "", MAX(0, I186 - (TODAY() - TODAY()))) -> 0 | M186: =IF(OR(I186="", H186=""), "", IF(I186<0, "Vencido", IF(I186>(H186/2), "Supere la mitad", "Bajo la mitad"))) -> Vencido | N186: CE-GC-0228 | O186: 46069 | P186: =IF(OR(O186="", J186=""), "", NETWORKDAYS(J186, O186, FESTIVOS!A185:A239)) -> -11
A187: OTRO | B187: OSCAR JAVIER RAMOS | C187: USUARIO DE SERVINTEGRAL | D187: Solicitud de apoyo para jornada de aseo y embellecimiento I.E. ANDES SEDE ALPES | E187: 186 | F187: 46062 | H187: =IF(A187="INFORMACIÓN O DOCUMENTOS", 10, IF(A187="CONSULTA", 30, IF(A187="FACTURACIÓN Y COBROS", 15, IF(A187="VINCULACIÓN Y DESVINCULACIÓN", 15, IF(A187="NO ES DE NUESTRA COMPETENCIA", 5, IF(A187="OTRO", 15, "")))))) -> 15 | I187: =IF(AND(F187<>"", J187<>""), NETWORKDAYS(TODAY(), J187-1, FESTIVOS!A$1:A$55), "") -> -68 | J187: =IF(AND(F187<>"", H187<>""), WORKDAY(F187, H187, FESTIVOS!A$1:A$55), "") -> 46083 | K187: LAURA GIRALDO | L187: =IF(I187="", "", MAX(0, I187 - (TODAY() - TODAY()))) -> 0 | M187: =IF(OR(I187="", H187=""), "", IF(I187<0, "Vencido", IF(I187>(H187/2), "Supere la mitad", "Bajo la mitad"))) -> Vencido | N187: CE-GC-0033 | O187: 46036 | P187: =IF(OR(O187="", J187=""), "", NETWORKDAYS(J187, O187, FESTIVOS!A186:A240)) -> -34
A188: OTRO | B188: ARISTIDES TOVAR | C188: USUARIO DE SERVINTEGRAL | D188: ENCUENTRO NACIONAL | E188: 187 | F188: 46062 | H188: =IF(A188="INFORMACIÓN O DOCUMENTOS", 10, IF(A188="CONSULTA", 30, IF(A188="FACTURACIÓN Y COBROS", 15, IF(A188="VINCULACIÓN Y DESVINCULACIÓN", 15, IF(A188="NO ES DE NUESTRA COMPETENCIA", 5, IF(A188="OTRO", 15, "")))))) -> 15 | I188: =IF(AND(F188<>"", J188<>""), NETWORKDAYS(TODAY(), J188-1, FESTIVOS!A$1:A$55), "") -> -68 | J188: =IF(AND(F188<>"", H188<>""), WORKDAY(F188, H188, FESTIVOS!A$1:A$55), "") -> 46083 | K188: LAURA GIRALDO | L188: =IF(I188="", "", MAX(0, I188 - (TODAY() - TODAY()))) -> 0 | M188: =IF(OR(I188="", H188=""), "", IF(I188<0, "Vencido", IF(I188>(H188/2), "Supere la mitad", "Bajo la mitad"))) -> Vencido | N188: CE-GC-0033 | O188: 46036 | P188: =IF(OR(O188="", J188=""), "", NETWORKDAYS(J188, O188, FESTIVOS!A187:A241)) -> -34
A189: OTRO | B189: QUEJA DEL SERVICIO | C189: USUARIO DE SERVINTEGRAL | D189: EVIDALIA LADINO | E189: 188 | F189: 46062 | H189: =IF(A189="INFORMACIÓN O DOCUMENTOS", 10, IF(A189="CONSULTA", 30, IF(A189="FACTURACIÓN Y COBROS", 15, IF(A189="VINCULACIÓN Y DESVINCULACIÓN", 15, IF(A189="NO ES DE NUESTRA COMPETENCIA", 5, IF(A189="OTRO", 15, "")))))) -> 15 | I189: =IF(AND(F189<>"", J189<>""), NETWORKDAYS(TODAY(), J189-1, FESTIVOS!A$1:A$55), "") -> -68 | J189: =IF(AND(F189<>"", H189<>""), WORKDAY(F189, H189, FESTIVOS!A$1:A$55), "") -> 46083 | K189: LAURA GIRALDO | L189: =IF(I189="", "", MAX(0, I189 - (TODAY() - TODAY()))) -> 0 | M189: =IF(OR(I189="", H189=""), "", IF(I189<0, "Vencido", IF(I189>(H189/2), "Supere la mitad", "Bajo la mitad"))) -> Vencido | N189: CE-GC-0033 | O189: 46036 | P189: =IF(OR(O189="", J189=""), "", NETWORKDAYS(J189, O189, FESTIVOS!A188:A242)) -> -34
A190: OTRO | B190: SIXTO ALFONSO PARAMO | C190: USUARIO DE SERVINTEGRAL | D190: COMUNICACIÓN DE ACTA MEDIANTE LA CUAL SE RESUELVE IMPUGNACIÓN FRENTE AL CASO MARIANO OSWALDO ROJAS ARANGO- C.C 94043507 Y SE REITERA EL DEBER DE ALLEGAR EL SOPORTE DE PAGO DE HONORARIOS A FAVOR DE LA JUNTA NACIONAL PARA EL TRÁMITE CORRESPONDIENTE | E190: 189 | F190: 46062 | H190: =IF(A190="INFORMACIÓN O DOCUMENTOS", 10, IF(A190="CONSULTA", 30, IF(A190="FACTURACIÓN Y COBROS", 15, IF(A190="VINCULACIÓN Y DESVINCULACIÓN", 15, IF(A190="NO ES DE NUESTRA COMPETENCIA", 5, IF(A190="OTRO", 15, "")))))) -> 15 | I190: =IF(AND(F190<>"", J190<>""), NETWORKDAYS(TODAY(), J190-1, FESTIVOS!A$1:A$55), "") -> -68 | J190: =IF(AND(F190<>"", H190<>""), WORKDAY(F190, H190, FESTIVOS!A$1:A$55), "") -> 46083 | K190: LAURA GIRALDO | L190: =IF(I190="", "", MAX(0, I190 - (TODAY() - TODAY()))) -> 0 | M190: =IF(OR(I190="", H190=""), "", IF(I190<0, "Vencido", IF(I190>(H190/2), "Supere la mitad", "Bajo la mitad"))) -> Vencido | N190: CE-GC-0033 | O190: 46036 | P190: =IF(OR(O190="", J190=""), "", NETWORKDAYS(J190, O190, FESTIVOS!A189:A243)) -> -34
A191: OTRO | B191: CAMILO ENRIQUE DIAZ CARDENAS | C191: USUARIO DE SERVINTEGRAL | D191: ACEPTACIÓN DE LA PROPUESTA | E191: 190 | F191: 46062 | H191: =IF(A191="INFORMACIÓN O DOCUMENTOS", 10, IF(A191="CONSULTA", 30, IF(A191="FACTURACIÓN Y COBROS", 15, IF(A191="VINCULACIÓN Y DESVINCULACIÓN", 15, IF(A191="NO ES DE NUESTRA COMPETENCIA", 5, IF(A191="OTRO", 15, "")))))) -> 15 | I191: =IF(AND(F191<>"", J191<>""), NETWORKDAYS(TODAY(), J191-1, FESTIVOS!A$1:A$55), "") -> -68 | J191: =IF(AND(F191<>"", H191<>""), WORKDAY(F191, H191, FESTIVOS!A$1:A$55), "") -> 46083 | K191: LAURA GIRALDO | L191: =IF(I191="", "", MAX(0, I191 - (TODAY() - TODAY()))) -> 0 | M191: =IF(OR(I191="", H191=""), "", IF(I191<0, "Vencido", IF(I191>(H191/2), "Supere la mitad", "Bajo la mitad"))) -> Vencido | N191: CE-GC-0033 | O191: 46036 | P191: =IF(OR(O191="", J191=""), "", NETWORKDAYS(J191, O191, FESTIVOS!A190:A244)) -> -34
...

Sheet FESTIVOS
A1: 45658
A2: 45663
A3: 45740
A4: 45764
A5: 45765
A6: 45778
A7: 45810
A8: 45831
A9: 45838
A10: 45858
A11: 45876
A12: 45887
... A55: 46746
